Workbook

Sheet Data
A1: Số TT | B1: Giấy chứng nhận | E1: Thông tin chủ sử dụng | Z1: Thông tin vợ (chồng) | AQ1: Thông tin thửa đất | CV1: Thông tin ký GCN | EE1: Thông tin về tài sản gắn liền với đất | FN1: Thông tin thửa đất cũ | FX1: Hồ sơ quét | GC1: Thông tin giao nộp
B2: Số serial | C2: Mã HS Gốc | D2: Mã vạch | E2: Mã Chủ SD | F2: ĐTSD | G2: HGD | H2: Người đại diện | I2: Họ tên | J2: Giới tính | K2: Ngày, tháng, năm sinh | L2: Năm sinh | M2: Loại GT | N2: Số giấy tờ | O2: Ngày cấp | P2: Nơi cấp | Q2: Địa chỉ chủ sử dụng | W2: Mã số thuế | X2: Dân tộc | Y2: Quốc tịch | Z2: Họ và tên | AA2: Giới tính | AB2: Ngày, tháng, năm sinh | AC2: Năm sinh | AD2: Loại GT | AE2: Số Giấy tờ | AF2: Ngày cấp | AG2: Nơi cấp | AH2: Địa chỉ vợ (chồng) | AN2: Mã số thuế | AO2: Dân tộc | AP2: Quốc tịch | AQ2: Số thửa | AR2: Số tờ | AS2: Tỷ lệ | AT2: Loại bản đồ | AU2: Đơn vị đo đạc | AV2: Phương pháp đo | AW2: Mức độ chính xác | AX2: Ngày hoàn thành | AY2: Phân loại thửa đất | AZ2: Diện tích bản đồ | BA2: Diện tích Pháp lý | BC2: Đa mục đích sử dụng 1 | BK2: Đa mục đích sử dụng 2 | BS2: Đa mục đích sử dụng 3 | CA2: Đa mục đích sử dụng 4 | CI2: Diện tích hành lang | CM2: Địa chỉ | CR2: Mã đơn | CS2: Ngày đăng ký đơn lần đầu | CT2: Mã hình thức SD | CU2: Trạng thái thửa đất | CV2: Loại GCN | CW2: Số vào sổ | CX2: Ngày vào sổ | CY2: Ngày ký GCN | CZ2: Người ký | DA2: Ủy quyền ký | DB2: Ký thay | DC2: Ngày cấp | DD2: Tên đợt cấp | DE2: Căn cứ pháp lý | DF2: Ghi chú trang 1 | DG2: Ghi chú trang 2 | DH2: Hạn chế quyền | DO2: Nghĩa vụ tài chính | DU2: Miễn giảm nghĩa vụ tài chính | DZ2: Nợ nghĩa vụ tài chính | EE2: Nhà ở riêng lẻ | EM2: Công trình, hạng mục công trình xây dựng | EZ2: Công trình ngầm | FH2: Rừng trồng | FK2: Cây lâu năm | FN2: Tờ bản đồ | FO2: Số thửa | FP2: Diện tích | FQ2: Loại đất GCN | FR2: Thời hạn | FS2: Nguồn gốc | FT2: Số Serial | FU2: Số vào sổ | FV2: Ngày cấp | FW2: Hình thức sử dụng | FX2: Thông tin lưu kho vật lý hồ sơ | GB2: Thư mục lưu HSQ | GC2: Đợt giao nộp | GD2: Trạng thái kiểm tra | GE2: Nội dung ghi chú
Q3: Địa chỉ chi tiết: Số nhà, ngõ phố… | R3: Đường Phố | S3: Tổ dân phố | T3: Mã xã/phường | U3: Xã, huyện, tỉnh | V3: Địa chỉ đầy đủ | AH3: Số nhà, ngõ phố,… | AI3: Đường Phố | AJ3: Tổ dân phố | AK3: Mã xã/Phường | AL3: Xã, huyện, tỉnh | AM3: Địa chỉ đầy đủ | BB3: Nháp | BC3: Mã MĐSD | BD3: Mã MĐSD Quy hoạch | BE3: Diện tích | BF3: Là SD chung | BG3: Thời hạn sử dụng | BH3: Nguồn gốc biến động | BI3: Nguồn gốc cấp GCN lần đầu | BJ3: Nguồn gốc chi tiết | BK3: Mã MĐSD | BL3: Mã MĐSD Quy hoạch | BM3: Diện tích | BN3: Là SD chung | BO3: Thời hạn sử dụng | BP3: Nguồn gốc biến động | BQ3: Nguồn gốc cấp GCN lần đầu | BR3: Nguồn gốc chi tiết | BS3: Mã MĐSD | BT3: Mã MĐSD Quy hoạch | BU3: Diện tích | BV3: Là SD chung | BW3: Thời hạn sử dụng | BX3: Nguồn gốc biến động | BY3: Nguồn gốc cấp GCN lần đầu | BZ3: Nguồn gốc chi tiết | CA3: Mã MĐSD | CB3: Mã MĐSD Quy hoạch | CC3: Diện tích | CD3: Là SD chung | CE3: Thời hạn sử dụng | CF3: Nguồn gốc biến động | CG3: Nguồn gốc cấp GCN lần đầu | CH3: Nguồn gốc chi tiết | CI3: Giao thông | CJ3: Lưới điện | CK3: Sông suối | CL3: Đường sắt | CM3: Số nhà, ngõ phố… | CN3: Đường Phố | CO3: Tổ dân phố | CP3: Xã, huyện, tỉnh | CQ3: Địa chỉ đầy đủ | DH3: Loại hạn chế | DI3: Diện tích | DJ3: Nội dung | DK3: Số văn bản | DL3: Ngày ban hành | DM3: Cơ quan ban hành | DN3: Hạn chế 1 phần | DO3: Loại NVTC | DP3: Tổng số tiền | DQ3: Tổng số tiền miễn giảm | DR3: Tổng số tiền nợ | DS3: Ngày bắt đầu | DT3: Ngày hoàn thành | DU3: Loại chế độ | DV3: Số tiền | DW3: Số văn bản | DX3: Ngày ban hành | DY3: Cơ quan ban hành | DZ3: Loại chế độ | EA3: Số tiền | EB3: Số quyết định | EC3: Ngày ban hành | ED3: Cơ quan ban hành | EE3: DT xây dựng | EF3: DT sàn | EG3: Số tầng | EH3: Số tầng hầm | EI3: Kết cấu | EJ3: Cấp hạng | EK3: Địa chỉ | EL3: Thời hạn sở hữu | EM3: Tên công trình | EN3: Địa chỉ | EO3: Tên hạng mục | EP3: Công năng | EQ3: DT xây dựng | ER3: DT sàn | ES3: Số tầng | ET3: Số tầng hầm | EU3: Kết cấu | EV3: Năm xây dựng | EW3: Năm hoàn thành | EX3: Thời hạn sở hữu | EY3: Cấp hạng | EZ3: Tên công trình | FA3: Loại công trình | FB3: Diện tích công trình | FC3: Độ sâu tối đa | FD3: Vị trí đầu nối | FE3: Năm xây dựng | FF3: Năm hoàn thành | FG3: Thời hạn sở hữu | FH3: Tên rừng | FI3: Loại cây rừng | FJ3: Diện tích | FK3: Tên cây lâu năm | FL3: Loại cây trồng | FM3: Diện tích | FX3: Kho | FY3: Giá | FZ3: Kệ | GA3: Ngăn
A4: 1 | B4: 2 | C4: 3 | D4: 4 | E4: 5 | F4: 6 | G4: 7 | H4: 8 | I4: 9 | J4: 10 | K4: 11 | L4: 12 | M4: 13 | N4: 14 | O4: 15 | P4: 16 | Q4: 17 | R4: 18 | S4: 19 | T4: 20 | U4: 21 | V4: 22 | W4: 23 | X4: 24 | Y4: 25 | Z4: 26 | AA4: 27 | AB4: 28 | AC4: 29 | AD4: 30 | AE4: 31 | AF4: 32 | AG4: 33 | AH4: 34 | AI4: 35 | AJ4: 36 | AK4: 37 | AL4: 38 | AM4: 39 | AN4: 40 | AO4: 41 | AP4: 42 | AQ4: 43 | AR4: 44 | AS4: 45 | AT4: 46 | AU4: 47 | AV4: 48 | AW4: 49 | AX4: 50 | AY4: 51 | AZ4: 52 | BA4: 53 | BC4: 54 | BD4: 55 | BE4: 56 | BF4: 57 | BG4: 58 | BH4: 59 | BI4: 60 | BJ4: 61 | BK4: 62 | BL4: 63 | BM4: 64 | BN4: 65 | BO4: 66 | BP4: 67 | BQ4: 68 | BR4: 69 | BS4: 70 | BT4: 71 | BU4: 72 | BV4: 73 | BW4: 74 | BX4: 75 | BY4: 76 | BZ4: 77 | CA4: 78 | CB4: 79 | CC4: 80 | CD4: 81 | CE4: 82 | CF4: 83 | CG4: 84 | CH4: 85 | CI4: 86 | CJ4: 87 | CK4: 88 | CL4: 89 | CM4: 90 | CN4: 91 | CO4: 92 | CP4: 93 | CQ4: 94 | CR4: 95 | CS4: 96 | CT4: 97 | CU4: 98 | CV4: 99 | CW4: 100 | CX4: 101 | CY4: 102 | CZ4: 103 | DA4: 104 | DB4: 105 | DC4: 106 | DD4: 107 | DE4: 108 | DF4: 109 | DG4: 110 | DH4: 111 | DI4: 112 | DJ4: 113 | DK4: 114 | DL4: 115 | DM4: 116 | DN4: 117 | DO4: 118 | DP4: 119 | DQ4: 120 | DR4: 121 | DS4: 122 | DT4: 123 | DU4: 124 | DV4: 125 | DW4: 126 | DX4: 127 | DY4: 128 | DZ4: 129 | EA4: 130 | EB4: 131 | EC4: 132 | ED4: 133 | EE4: 134 | EF4: 135 | EG4: 136 | EH4: 137 | EI4: 138 | EJ4: 139 | EK4: 140 | EL4: 141 | EM4: 142 | EN4: 143 | EO4: 144 | EP4: 145 | EQ4: 146 | ER4: 147 | ES4: 148 | ET4: 149 | EU4: 150 | EV4: 151 | EW4: 152 | EX4: 153 | EY4: 154 | EZ4: 155 | FA4: 156 | FB4: 157 | FC4: 158 | FD4: 159 | FE4: 160 | FF4: 161 | FG4: 162 | FH4: 163 | FI4: 164 | FJ4: 165 | FK4: 166 | FL4: 167 | FM4: 168 | FN4: 169 | FO4: 170 | FP4: 171 | FQ4: 172 | FR4: 173 | FS4: 174 | FT4: 175 | FU4: 176 | FV4: 177 | FW4: 178 | FX4: 179 | FY4: 180 | FZ4: 181 | GA4: 182 | GB4: 183 | GC4: 184 | GD4: 185 | GE4: 186
A5: 1 | C5: =RIGHT(D5,6) -> 005157 | D5: 0691019005157 | F5: GDC | G5: 1 | I5: Phạm Như Hiên | J5: 1 | L5: 1972 | M5: CMND | N5: 100574721 | S5: Thôn Đông | T5: =VLOOKUP(U5,MaXa_3cap_2cap!$B$2:$C$369,2,0) -> 06910 | U5: xã Dực Yên, huyện Đầm Hà, tỉnh Quảng Ninh | V5: Thôn Đông, xã Dực Yên, huyện Đầm Hà, tỉnh Quảng Ninh | Y5: Việt Nam | Z5: Lương Thị Hoà | AA5: 0 | AC5: 1973 | AD5: CMND | AE5: 100597591 | AJ5: Thôn Đông | AK5: =VLOOKUP(AL5,MaXa_3cap_2cap!$B$2:$C$369,2,0) -> 06910 | AL5: xã Dực Yên, huyện Đầm Hà, tỉnh Quảng Ninh | AM5: Thôn Đông, xã Dực Yên, huyện Đầm Hà, tỉnh Quảng Ninh | AP5: Việt Nam | AQ5: 26 | AR5: 54 | AS5: 1000 | AU5: =VLOOKUP(CP5,'TT DO DAC'!$B$2:$G$213,5,0) -> Chi nhánh xí nghiệp tài nguyên và môi trường 7 | AX5: =VLOOKUP(CP5,'TT DO DAC'!$B$2:$G$213,6,0) -> 41274 | AY5: A | BB5: Đất chuyên trồng lúa | BC5: =VLOOKUP(BB5,DM_LoaiDat!$B$2:$C$78,2,0) -> LUC | BD5: =BC5 -> LUC | BE5: 546.9 | BF5: 0 | BG5: Đến ngày 17/08/2067 | BI5: DG-KTT | BJ5: =VLOOKUP(BI5,DM_NguonGocSuDungDat!$A$2:$B$24,2,0) -> Nhà nước giao đất không thu tiền sử dụng đất | CP5: xã Dực Yên, huyện Đầm Hà, tỉnh Quảng Ninh | CQ5: Thôn Đông, xã Dực Yên, huyện Đầm Hà, tỉnh Quảng Ninh | CT5: 0 | CV5: Giấy chứng nhận QSDĐ & QSHNƠ và TSKGLVĐ theo NĐ 88/NĐ-CP | CW5: CH 002268 | CY5: 44055 | CZ5: Lê Bình Phượng | DA5: 0 | DB5: 1 | DC5: 2020 | GB5: CT 909104
A6: 2 | C6: =RIGHT(D6,6) -> 005157 | D6: 0691019005157 | F6: GDC | G6: 1 | I6: Phạm Như Hiên | J6: 1 | L6: 1972 | M6: CMND | N6: 100574721 | S6: Thôn Đông | T6: =VLOOKUP(U6,MaXa_3cap_2cap!$B$2:$C$369,2,0) -> 06910 | U6: xã Dực Yên, huyện Đầm Hà, tỉnh Quảng Ninh | V6: Thôn Đông, xã Dực Yên, huyện Đầm Hà, tỉnh Quảng Ninh | Y6: Việt Nam | Z6: Lương Thị Hoà | AA6: 0 | AC6: 1973 | AD6: CMND | AE6: 100597591 | AJ6: Thôn Đông | AK6: =VLOOKUP(AL6,MaXa_3cap_2cap!$B$2:$C$369,2,0) -> 06910 | AL6: xã Dực Yên, huyện Đầm Hà, tỉnh Quảng Ninh | AM6: Thôn Đông, xã Dực Yên, huyện Đầm Hà, tỉnh Quảng Ninh | AP6: Việt Nam | AQ6: 48 | AR6: 55 | AS6: 1000 | AU6: =VLOOKUP(CP6,'TT DO DAC'!$B$2:$G$213,5,0) -> Chi nhánh xí nghiệp tài nguyên và môi trường 7 | AX6: =VLOOKUP(CP6,'TT DO DAC'!$B$2:$G$213,6,0) -> 41274 | AY6: A | BB6: Đất trồng cây hằng năm khác | BC6: =VLOOKUP(BB6,DM_LoaiDat!$B$2:$C$78,2,0) -> HNK | BD6: =BC6 -> HNK | BE6: 217.7 | BF6: 0 | BG6: Đến ngày 17/08/2067 | BI6: DG-KTT | BJ6: =VLOOKUP(BI6,DM_NguonGocSuDungDat!$A$2:$B$24,2,0) -> Nhà nước giao đất không thu tiền sử dụng đất | CP6: xã Dực Yên, huyện Đầm Hà, tỉnh Quảng Ninh | CQ6: Thôn Đông, xã Dực Yên, huyện Đầm Hà, tỉnh Quảng Ninh | CT6: 0 | CV6: Giấy chứng nhận QSDĐ & QSHNƠ và TSKGLVĐ theo NĐ 88/NĐ-CP | CW6: CH 002268 | CY6: 44055 | CZ6: Lê Bình Phượng | DA6: 0 | DB6: 1 | DC6: 2020 | GB6: CT 909104
A7: 3 | C7: =RIGHT(D7,6) -> 005157 | D7: 0691019005157 | F7: GDC | G7: 1 | I7: Phạm Như Hiên | J7: 1 | L7: 1972 | M7: CMND | N7: 100574721 | S7: Thôn Đông | T7: =VLOOKUP(U7,MaXa_3cap_2cap!$B$2:$C$369,2,0) -> 06910 | U7: xã Dực Yên, huyện Đầm Hà, tỉnh Quảng Ninh | V7: Thôn Đông, xã Dực Yên, huyện Đầm Hà, tỉnh Quảng Ninh | Y7: Việt Nam | Z7: Lương Thị Hoà | AA7: 0 | AC7: 1973 | AD7: CMND | AE7: 100597591 | AJ7: Thôn Đông | AK7: =VLOOKUP(AL7,MaXa_3cap_2cap!$B$2:$C$369,2,0) -> 06910 | AL7: xã Dực Yên, huyện Đầm Hà, tỉnh Quảng Ninh | AM7: Thôn Đông, xã Dực Yên, huyện Đầm Hà, tỉnh Quảng Ninh | AP7: Việt Nam | AQ7: 220 | AR7: 55 | AS7: 1000 | AU7: =VLOOKUP(CP7,'TT DO DAC'!$B$2:$G$213,5,0) -> Chi nhánh xí nghiệp tài nguyên và môi trường 7 | AX7: =VLOOKUP(CP7,'TT DO DAC'!$B$2:$G$213,6,0) -> 41274 | AY7: A | BB7: Đất trồng lúa còn lại | BC7: =VLOOKUP(BB7,DM_LoaiDat!$B$2:$C$78,2,0) -> LUK | BD7: =BC7 -> LUK | BE7: 370.8 | BF7: 0 | BG7: Đến ngày 17/08/2067 | BI7: DG-KTT | BJ7: =VLOOKUP(BI7,DM_NguonGocSuDungDat!$A$2:$B$24,2,0) -> Nhà nước giao đất không thu tiền sử dụng đất | CP7: xã Dực Yên, huyện Đầm Hà, tỉnh Quảng Ninh | CQ7: Thôn Đông, xã Dực Yên, huyện Đầm Hà, tỉnh Quảng Ninh | CT7: 0 | CV7: Giấy chứng nhận QSDĐ & QSHNƠ và TSKGLVĐ theo NĐ 88/NĐ-CP | CW7: CH 002268 | CY7: 44055 | CZ7: Lê Bình Phượng | DA7: 0 | DB7: 1 | DC7: 2020 | GB7: CT 909104
A8: 4 | C8: =RIGHT(D8,6) -> 005157 | D8: 0691019005157 | F8: GDC | G8: 1 | I8: Phạm Như Hiên | J8: 1 | L8: 1972 | M8: CMND | N8: 100574721 | S8: Thôn Đông | T8: =VLOOKUP(U8,MaXa_3cap_2cap!$B$2:$C$369,2,0) -> 06910 | U8: xã Dực Yên, huyện Đầm Hà, tỉnh Quảng Ninh | V8: Thôn Đông, xã Dực Yên, huyện Đầm Hà, tỉnh Quảng Ninh | Y8: Việt Nam | Z8: Lương Thị Hoà | AA8: 0 | AC8: 1973 | AD8: CMND | AE8: 100597591 | AJ8: Thôn Đông | AK8: =VLOOKUP(AL8,MaXa_3cap_2cap!$B$2:$C$369,2,0) -> 06910 | AL8: xã Dực Yên, huyện Đầm Hà, tỉnh Quảng Ninh | AM8: Thôn Đông, xã Dực Yên, huyện Đầm Hà, tỉnh Quảng Ninh | AP8: Việt Nam | AQ8: 253 | AR8: 55 | AS8: 1000 | AU8: =VLOOKUP(CP8,'TT DO DAC'!$B$2:$G$213,5,0) -> Chi nhánh xí nghiệp tài nguyên và môi trường 7 | AX8: =VLOOKUP(CP8,'TT DO DAC'!$B$2:$G$213,6,0) -> 41274 | AY8: A | BB8: Đất trồng lúa còn lại | BC8: =VLOOKUP(BB8,DM_LoaiDat!$B$2:$C$78,2,0) -> LUK | BD8: =BC8 -> LUK | BE8: 515.7 | BF8: 0 | BG8: Đến ngày 17/08/2067 | BI8: DG-KTT | BJ8: =VLOOKUP(BI8,DM_NguonGocSuDungDat!$A$2:$B$24,2,0) -> Nhà nước giao đất không thu tiền sử dụng đất | CP8: xã Dực Yên, huyện Đầm Hà, tỉnh Quảng Ninh | CQ8: Thôn Đông, xã Dực Yên, huyện Đầm Hà, tỉnh Quảng Ninh | CT8: 0 | CV8: Giấy chứng nhận QSDĐ & QSHNƠ và TSKGLVĐ theo NĐ 88/NĐ-CP | CW8: CH 002268 | CY8: 44055 | CZ8: Lê Bình Phượng | DA8: 0 | DB8: 1 | DC8: 2020 | GB8: CT 909104
A9: 0.60416667
A10: 1 | B10: CT 909066 | C10: =RIGHT(D10,6) -> 005374 | D10: 0691019005374 | F10: GDC | G10: 1 | I10: Nguyễn Văn Quý | J10: 1 | L10: 1964 | M10: CMND | N10: 100574726 | S10: Thôn Tây | T10: =VLOOKUP(U10,MaXa_3cap_2cap!$B$2:$C$369,2,0) -> 06910 | U10: xã Dực Yên, huyện Đầm Hà, tỉnh Quảng Ninh | V10: Thôn Tây, xã Dực Yên, huyện Đầm Hà, tỉnh Quảng Ninh | Y10: Việt Nam | Z10: Đặng Thị Thủy | AA10: 0 | AC10: 1966 | AD10: CMND | AE10: 100691620 | AJ10: Thôn Tây | AK10: =VLOOKUP(AL10,MaXa_3cap_2cap!$B$2:$C$369,2,0) -> 06910 | AL10: xã Dực Yên, huyện Đầm Hà, tỉnh Quảng Ninh | AM10: Thôn Tây, xã Dực Yên, huyện Đầm Hà, tỉnh Quảng Ninh | AP10: Việt Nam | AQ10: 130 | AR10: 41 | AS10: 1000 | AU10: =VLOOKUP(CP10,'TT DO DAC'!$B$2:$G$213,5,0) -> Chi nhánh xí nghiệp tài nguyên và môi trường 7 | AX10: =VLOOKUP(CP10,'TT DO DAC'!$B$2:$G$213,6,0) -> 41274 | AY10: A | BB10: Đất chuyên trồng lúa | BC10: =VLOOKUP(BB10,DM_LoaiDat!$B$2:$C$78,2,0) -> LUC | BD10: =BC10 -> LUC | BE10: 459.1 | BF10: 0 | BG10: Đến ngày 17/08/2068 | BI10: DG-KTT | BJ10: =VLOOKUP(BI10,DM_NguonGocSuDungDat!$A$2:$B$24,2,0) -> Nhà nước giao đất không thu tiền sử dụng đất | CP10: xã Dực Yên, huyện Đầm Hà, tỉnh Quảng Ninh | CQ10: Thôn Tây, xã Dực Yên, huyện Đầm Hà, tỉnh Quảng Ninh | CT10: 0 | CV10: Giấy chứng nhận QSDĐ & QSHNƠ và TSKGLVĐ theo NĐ 88/NĐ-CP | CW10: CH 00547 | CY10: 20/9/2021 | CZ10: Lê Bình Phượng | DA10: 0 | DB10: 1 | DC10: 2021 | GB10: CT 909066
A11: 2 | B11: CT 909066 | C11: =RIGHT(D11,6) -> 005374 | D11: 0691019005374 | F11: GDC | G11: 1 | I11: Nguyễn Văn Quý | J11: 1 | L11: 1964 | M11: CMND | N11: 100574726 | S11: Thôn Tây | T11: =VLOOKUP(U11,MaXa_3cap_2cap!$B$2:$C$369,2,0) -> 06910 | U11: xã Dực Yên, huyện Đầm Hà, tỉnh Quảng Ninh | V11: Thôn Tây, xã Dực Yên, huyện Đầm Hà, tỉnh Quảng Ninh | Y11: Việt Nam | Z11: Đặng Thị Thủy | AA11: 0 | AC11: 1966 | AD11: CMND | AE11: 100691620 | AJ11: Thôn Tây | AK11: =VLOOKUP(AL11,MaXa_3cap_2cap!$B$2:$C$369,2,0) -> 06910 | AL11: xã Dực Yên, huyện Đầm Hà, tỉnh Quảng Ninh | AM11: Thôn Tây, xã Dực Yên, huyện Đầm Hà, tỉnh Quảng Ninh | AP11: Việt Nam | AQ11: 112 | AR11: 40 | AS11: 1000 | AU11: =VLOOKUP(CP11,'TT DO DAC'!$B$2:$G$213,5,0) -> Chi nhánh xí nghiệp tài nguyên và môi trường 7 | AX11: =VLOOKUP(CP11,'TT DO DAC'!$B$2:$G$213,6,0) -> 41274 | AY11: A | BB11: Đất trồng lúa còn lại | BC11: =VLOOKUP(BB11,DM_LoaiDat!$B$2:$C$78,2,0) -> LUK | BD11: =BC11 -> LUK | BE11: 620.8 | BF11: 0 | BG11: Đến ngày 17/08/2068 | BI11: DG-KTT | BJ11: =VLOOKUP(BI11,DM_NguonGocSuDungDat!$A$2:$B$24,2,0) -> Nhà nước giao đất không thu tiền sử dụng đất | CP11: xã Dực Yên, huyện Đầm Hà, tỉnh Quảng Ninh | CQ11: Thôn Tây, xã Dực Yên, huyện Đầm Hà, tỉnh Quảng Ninh | CT11: 0 | CV11: Giấy chứng nhận QSDĐ & QSHNƠ và TSKGLVĐ theo NĐ 88/NĐ-CP | CW11: CH 00547 | CY11: 20/9/2021 | CZ11: Lê Bình Phượng | DA11: 0 | DB11: 1 | DC11: 2021 | GB11: CT 909067
A12: 3 | B12: CT 909066 | C12: =RIGHT(D12,6) -> 005374 | D12: 0691019005374 | F12: GDC | G12: 1 | I12: Nguyễn Văn Quý | J12: 1 | L12: 1964 | M12: CMND | N12: 100574726 | S12: Thôn Tây | T12: =VLOOKUP(U12,MaXa_3cap_2cap!$B$2:$C$369,2,0) -> 06910 | U12: xã Dực Yên, huyện Đầm Hà, tỉnh Quảng Ninh | V12: Thôn Tây, xã Dực Yên, huyện Đầm Hà, tỉnh Quảng Ninh | Y12: Việt Nam | Z12: Đặng Thị Thủy | AA12: 0 | AC12: 1966 | AD12: CMND | AE12: 100691620 | AJ12: Thôn Tây | AK12: =VLOOKUP(AL12,MaXa_3cap_2cap!$B$2:$C$369,2,0) -> 06910 | AL12: xã Dực Yên, huyện Đầm Hà, tỉnh Quảng Ninh | AM12: Thôn Tây, xã Dực Yên, huyện Đầm Hà, tỉnh Quảng Ninh | AP12: Việt Nam | AQ12: 97 | AR12: 40 | AS12: 1000 | AU12: =VLOOKUP(CP12,'TT DO DAC'!$B$2:$G$213,5,0) -> Chi nhánh xí nghiệp tài nguyên và môi trường 7 | AX12: =VLOOKUP(CP12,'TT DO DAC'!$B$2:$G$213,6,0) -> 41274 | AY12: A | BB12: Đất trồng lúa còn lại | BC12: =VLOOKUP(BB12,DM_LoaiDat!$B$2:$C$78,2,0) -> LUK | BD12: =BC12 -> LUK | BE12: 164.9 | BF12: 0 | BG12: Đến ngày 17/08/2068 | BI12: DG-KTT | BJ12: =VLOOKUP(BI12,DM_NguonGocSuDungDat!$A$2:$B$24,2,0) -> Nhà nước giao đất không thu tiền sử dụng đất | CP12: xã Dực Yên, huyện Đầm Hà, tỉnh Quảng Ninh | CQ12: Thôn Tây, xã Dực Yên, huyện Đầm Hà, tỉnh Quảng Ninh | CT12: 0 | CV12: Giấy chứng nhận QSDĐ & QSHNƠ và TSKGLVĐ theo NĐ 88/NĐ-CP | CW12: CH 00547 | CY12: 20/9/2021 | CZ12: Lê Bình Phượng | DA12: 0 | DB12: 1 | DC12: 2021 | GB12: CT 909068
A13: 4 | B13: CT 909066 | C13: =RIGHT(D13,6) -> 005374 | D13: 0691019005374 | F13: GDC | G13: 1 | I13: Nguyễn Văn Quý | J13: 1 | L13: 1964 | M13: CMND | N13: 100574726 | S13: Thôn Tây | T13: =VLOOKUP(U13,MaXa_3cap_2cap!$B$2:$C$369,2,0) -> 06910 | U13: xã Dực Yên, huyện Đầm Hà, tỉnh Quảng Ninh | V13: Thôn Tây, xã Dực Yên, huyện Đầm Hà, tỉnh Quảng Ninh | Y13: Việt Nam | Z13: Đặng Thị Thủy | AA13: 0 | AC13: 1966 | AD13: CMND | AE13: 100691620 | AJ13: Thôn Tây | AK13: =VLOOKUP(AL13,MaXa_3cap_2cap!$B$2:$C$369,2,0) -> 06910 | AL13: xã Dực Yên, huyện Đầm Hà, tỉnh Quảng Ninh | AM13: Thôn Tây, xã Dực Yên, huyện Đầm Hà, tỉnh Quảng Ninh | AP13: Việt Nam | AQ13: 77 | AR13: 40 | AS13: 1000 | AU13: =VLOOKUP(CP13,'TT DO DAC'!$B$2:$G$213,5,0) -> Chi nhánh xí nghiệp tài nguyên và môi trường 7 | AX13: =VLOOKUP(CP13,'TT DO DAC'!$B$2:$G$213,6,0) -> 41274 | AY13: A | BB13: Đất chuyên trồng lúa | BC13: =VLOOKUP(BB13,DM_LoaiDat!$B$2:$C$78,2,0) -> LUC | BD13: =BC13 -> LUC | BE13: 452.8 | BF13: 0 | BG13: Đến ngày 17/08/2068 | BI13: DG-KTT | BJ13: =VLOOKUP(BI13,DM_NguonGocSuDungDat!$A$2:$B$24,2,0) -> Nhà nước giao đất không thu tiền sử dụng đất | CP13: xã Dực Yên, huyện Đầm Hà, tỉnh Quảng Ninh | CQ13: Thôn Tây, xã Dực Yên, huyện Đầm Hà, tỉnh Quảng Ninh | CT13: 0 | CV13: Giấy chứng nhận QSDĐ & QSHNƠ và TSKGLVĐ theo NĐ 88/NĐ-CP | CW13: CH 00547 | CY13: 20/9/2021 | CZ13: Lê Bình Phượng | DA13: 0 | DB13: 1 | DC13: 2021 | GB13: CT 909069
A14: 0.61944444
A15: 5 | B15: CT 909057 | C15: =RIGHT(D15,6) -> 005365 | D15: 0691019005365 | F15: GDC | G15: 1 | I15: Đặng Văn Mươi | J15: 1 | L15: 1956 | M15: CMND | N15: 101235571 | S15: Thôn Tây | T15: =VLOOKUP(U15,MaXa_3cap_2cap!$B$2:$C$369,2,0) -> 06910 | U15: xã Dực Yên, huyện Đầm Hà, tỉnh Quảng Ninh | V15: Thôn Tây, xã Dực Yên, huyện Đầm Hà, tỉnh Quảng Ninh | Y15: Việt Nam | Z15: Trần Thị Hải | AA15: 0 | AC15: 1957 | AD15: CCCD | AE15: 030157001826 | AJ15: Thôn Tây | AK15: =VLOOKUP(AL15,MaXa_3cap_2cap!$B$2:$C$369,2,0) -> 06910 | AL15: xã Dực Yên, huyện Đầm Hà, tỉnh Quảng Ninh | AM15: Thôn Tây, xã Dực Yên, huyện Đầm Hà, tỉnh Quảng Ninh | AP15: Việt Nam | AQ15: 120 | AR15: 35 | AS15: 1000 | AU15: =VLOOKUP(CP15,'TT DO DAC'!$B$2:$G$213,5,0) -> Chi nhánh xí nghiệp tài nguyên và môi trường 7 | AX15: =VLOOKUP(CP15,'TT DO DAC'!$B$2:$G$213,6,0) -> 41274 | AY15: A | BB15: Đất trồng lúa còn lại | BC15: =VLOOKUP(BB15,DM_LoaiDat!$B$2:$C$78,2,0) -> LUK | BD15: =BC15 -> LUK | BE15: 449 | BF15: 0 | BG15: Đến ngày 17/08/2067 | BI15: DG-KTT | BJ15: =VLOOKUP(BI15,DM_NguonGocSuDungDat!$A$2:$B$24,2,0) -> Nhà nước giao đất không thu tiền sử dụng đất | CP15: xã Dực Yên, huyện Đầm Hà, tỉnh Quảng Ninh | CQ15: Thôn Tây, xã Dực Yên, huyện Đầm Hà, tỉnh Quảng Ninh | CT15: 0 | CV15: Giấy chứng nhận QSDĐ & QSHNƠ và TSKGLVĐ theo NĐ 88/NĐ-CP | CW15: CH 00552 | CY15: 21/09/2021 | CZ15: Lê Bình Phượng | DA15: 0 | DB15: 1 | DC15: 2021 | GB15: CT 909057
A16: 6 | B16: CT 909057 | C16: =RIGHT(D16,6) -> 005365 | D16: 0691019005365 | F16: GDC | G16: 1 | I16: Đặng Văn Mươi | J16: 1 | L16: 1956 | M16: CMND | N16: 101235571 | S16: Thôn Tây | T16: =VLOOKUP(U16,MaXa_3cap_2cap!$B$2:$C$369,2,0) -> 06910 | U16: xã Dực Yên, huyện Đầm Hà, tỉnh Quảng Ninh | V16: Thôn Tây, xã Dực Yên, huyện Đầm Hà, tỉnh Quảng Ninh | Y16: Việt Nam | Z16: Trần Thị Hải | AA16: 0 | AC16: 1957 | AD16: CCCD | AE16: 030157001826 | AJ16: Thôn Tây | AK16: =VLOOKUP(AL16,MaXa_3cap_2cap!$B$2:$C$369,2,0) -> 06910 | AL16: xã Dực Yên, huyện Đầm Hà, tỉnh Quảng Ninh | AM16: Thôn Tây, xã Dực Yên, huyện Đầm Hà, tỉnh Quảng Ninh | AP16: Việt Nam | AQ16: 117 | AR16: 35 | AS16: 1000 | AU16: =VLOOKUP(CP16,'TT DO DAC'!$B$2:$G$213,5,0) -> Chi nhánh xí nghiệp tài nguyên và môi trường 7 | AX16: =VLOOKUP(CP16,'TT DO DAC'!$B$2:$G$213,6,0) -> 41274 | AY16: A | BB16: Đất trồng lúa còn lại | BC16: =VLOOKUP(BB16,DM_LoaiDat!$B$2:$C$78,2,0) -> LUK | BD16: =BC16 -> LUK | BE16: 565.1 | BF16: 0 | BG16: Đến ngày 17/08/2067 | BI16: DG-KTT | BJ16: =VLOOKUP(BI16,DM_NguonGocSuDungDat!$A$2:$B$24,2,0) -> Nhà nước giao đất không thu tiền sử dụng đất | CP16: xã Dực Yên, huyện Đầm Hà, tỉnh Quảng Ninh | CQ16: Thôn Tây, xã Dực Yên, huyện Đầm Hà, tỉnh Quảng Ninh | CT16: 0 | CV16: Giấy chứng nhận QSDĐ & QSHNƠ và TSKGLVĐ theo NĐ 88/NĐ-CP | CW16: CH 00552 | CY16: 21/09/2021 | CZ16: Lê Bình Phượng | DA16: 0 | DB16: 1 | DC16: 2021 | GB16: CT 909057
A17: 7 | B17: CT 909057 | C17: =RIGHT(D17,6) -> 005365 | D17: 0691019005365 | F17: GDC | G17: 1 | I17: Đặng Văn Mươi | J17: 1 | L17: 1956 | M17: CMND | N17: 101235571 | S17: Thôn Tây | T17: =VLOOKUP(U17,MaXa_3cap_2cap!$B$2:$C$369,2,0) -> 06910 | U17: xã Dực Yên, huyện Đầm Hà, tỉnh Quảng Ninh | V17: Thôn Tây, xã Dực Yên, huyện Đầm Hà, tỉnh Quảng Ninh | Y17: Việt Nam | Z17: Trần Thị Hải | AA17: 0 | AC17: 1957 | AD17: CCCD | AE17: 030157001826 | AJ17: Thôn Tây | AK17: =VLOOKUP(AL17,MaXa_3cap_2cap!$B$2:$C$369,2,0) -> 06910 | AL17: xã Dực Yên, huyện Đầm Hà, tỉnh Quảng Ninh | AM17: Thôn Tây, xã Dực Yên, huyện Đầm Hà, tỉnh Quảng Ninh | AP17: Việt Nam | AQ17: 70 | AR17: 35 | AS17: 1000 | AU17: =VLOOKUP(CP17,'TT DO DAC'!$B$2:$G$213,5,0) -> Chi nhánh xí nghiệp tài nguyên và môi trường 7 | AX17: =VLOOKUP(CP17,'TT DO DAC'!$B$2:$G$213,6,0) -> 41274 | AY17: A | BB17: Đất trồng lúa còn lại | BC17: =VLOOKUP(BB17,DM_LoaiDat!$B$2:$C$78,2,0) -> LUK | BD17: =BC17 -> LUK | BE17: 1256.7 | BF17: 0 | BG17: Đến ngày 17/08/2067 | BI17: DG-KTT | BJ17: =VLOOKUP(BI17,DM_NguonGocSuDungDat!$A$2:$B$24,2,0) -> Nhà nước giao đất không thu tiền sử dụng đất | CP17: xã Dực Yên, huyện Đầm Hà, tỉnh Quảng Ninh | CQ17: Thôn Tây, xã Dực Yên, huyện Đầm Hà, tỉnh Quảng Ninh | CT17: 0 | CV17: Giấy chứng nhận QSDĐ & QSHNƠ và TSKGLVĐ theo NĐ 88/NĐ-CP | CW17: CH 00552 | CY17: 21/09/2021 | CZ17: Lê Bình Phượng | DA17: 0 | DB17: 1 | DC17: 2021 | GB17: CT 909057
A18: 8 | B18: CT 909057 | C18: =RIGHT(D18,6) -> 005365 | D18: 0691019005365 | F18: GDC | G18: 1 | I18: Đặng Văn Mươi | J18: 1 | L18: 1956 | M18: CMND | N18: 101235571 | S18: Thôn Tây | T18: =VLOOKUP(U18,MaXa_3cap_2cap!$B$2:$C$369,2,0) -> 06910 | U18: xã Dực Yên, huyện Đầm Hà, tỉnh Quảng Ninh | V18: Thôn Tây, xã Dực Yên, huyện Đầm Hà, tỉnh Quảng Ninh | Y18: Việt Nam | Z18: Trần Thị Hải | AA18: 0 | AC18: 1957 | AD18: CCCD | AE18: 030157001826 | AJ18: Thôn Tây | AK18: =VLOOKUP(AL18,MaXa_3cap_2cap!$B$2:$C$369,2,0) -> 06910 | AL18: xã Dực Yên, huyện Đầm Hà, tỉnh Quảng Ninh | AM18: Thôn Tây, xã Dực Yên, huyện Đầm Hà, tỉnh Quảng Ninh | AP18: Việt Nam | AQ18: 55 | AR18: 35 | AS18: 1000 | AU18: =VLOOKUP(CP18,'TT DO DAC'!$B$2:$G$213,5,0) -> Chi nhánh xí nghiệp tài nguyên và môi trường 7 | AX18: =VLOOKUP(CP18,'TT DO DAC'!$B$2:$G$213,6,0) -> 41274 | AY18: A | BB18: Đất trồng cây hằng năm khác | BC18: =VLOOKUP(BB18,DM_LoaiDat!$B$2:$C$78,2,0) -> HNK | BD18: =BC18 -> HNK | BE18: 140.4 | BF18: 0 | BG18: Đến ngày 17/08/2067 | BI18: DG-KTT | BJ18: =VLOOKUP(BI18,DM_NguonGocSuDungDat!$A$2:$B$24,2,0) -> Nhà nước giao đất không thu tiền sử dụng đất | CP18: xã Dực Yên, huyện Đầm Hà, tỉnh Quảng Ninh | CQ18: Thôn Tây, xã Dực Yên, huyện Đầm Hà, tỉnh Quảng Ninh | CT18: 0 | CV18: Giấy chứng nhận QSDĐ & QSHNƠ và TSKGLVĐ theo NĐ 88/NĐ-CP | CW18: CH 00552 | CY18: 21/09/2021 | CZ18: Lê Bình Phượng | DA18: 0 | DB18: 1 | DC18: 2021 | GB18: CT 909057
A19: 0.63333333 | C19: =RIGHT(D19,6)
A20: 9 | B20: CT 909068 | C20: =RIGHT(D20,6) -> 005376 | D20: 0691019005376 | F20: GDC | G20: 1 | I20: Hoàng Văn Phương | J20: 1 | L20: 1968 | M20: CMND | N20: 100470947 | S20: Thôn Tây | T20: =VLOOKUP(U20,MaXa_3cap_2cap!$B$2:$C$369,2,0) -> 06910 | U20: xã Dực Yên, huyện Đầm Hà, tỉnh Quảng Ninh | V20: Thôn Tây, xã Dực Yên, huyện Đầm Hà, tỉnh Quảng Ninh | Y20: Việt Nam | Z20: Nguyễn Thị Hảo | AA20: 0 | AC20: 1972 | AD20: CMND | AE20: 100691675 | AJ20: Thôn Tây | AK20: =VLOOKUP(AL20,MaXa_3cap_2cap!$B$2:$C$369,2,0) -> 06910 | AL20: xã Dực Yên, huyện Đầm Hà, tỉnh Quảng Ninh | AM20: Thôn Tây, xã Dực Yên, huyện Đầm Hà, tỉnh Quảng Ninh | AP20: Việt Nam | AQ20: 150 | AR20: 43 | AS20: 1000 | AU20: =VLOOKUP(CP20,'TT DO DAC'!$B$2:$G$213,5,0) -> Chi nhánh xí nghiệp tài nguyên và môi trường 7 | AX20: =VLOOKUP(CP20,'TT DO DAC'!$B$2:$G$213,6,0) -> 41274 | AY20: A | BB20: Đất chuyên trồng lúa | BC20: =VLOOKUP(BB20,DM_LoaiDat!$B$2:$C$78,2,0) -> LUC | BD20: =BC20 -> LUC | BE20: 635.2 | BF20: 0 | BG20: Đến ngày 17/08/2067 | BI20: DG-KTT | BJ20: =VLOOKUP(BI20,DM_NguonGocSuDungDat!$A$2:$B$24,2,0) -> Nhà nước giao đất không thu tiền sử dụng đất | CP20: xã Dực Yên, huyện Đầm Hà, tỉnh Quảng Ninh | CQ20: Thôn Tây, xã Dực Yên, huyện Đầm Hà, tỉnh Quảng Ninh | CT20: 0 | CV20: Giấy chứng nhận QSDĐ & QSHNƠ và TSKGLVĐ theo NĐ 88/NĐ-CP | CW20: CH 00493 | CY20: 25/02/2021 | CZ20: Lê Bình Phượng | DA20: 0 | DB20: 1 | DC20: 2021 | GB20: CT 909068
A21: 10 | B21: CT 909068 | C21: =RIGHT(D21,6) -> 005376 | D21: 0691019005376 | F21: GDC | G21: 1 | I21: Hoàng Văn Phương | J21: 1 | L21: 1968 | M21: CMND | N21: 100470947 | S21: Thôn Tây | T21: =VLOOKUP(U21,MaXa_3cap_2cap!$B$2:$C$369,2,0) -> 06910 | U21: xã Dực Yên, huyện Đầm Hà, tỉnh Quảng Ninh | V21: Thôn Tây, xã Dực Yên, huyện Đầm Hà, tỉnh Quảng Ninh | Y21: Việt Nam | Z21: Nguyễn Thị Hảo | AA21: 0 | AC21: 1972 | AD21: CMND | AE21: 100691675 | AJ21: Thôn Tây | AK21: =VLOOKUP(AL21,MaXa_3cap_2cap!$B$2:$C$369,2,0) -> 06910 | AL21: xã Dực Yên, huyện Đầm Hà, tỉnh Quảng Ninh | AM21: Thôn Tây, xã Dực Yên, huyện Đầm Hà, tỉnh Quảng Ninh | AP21: Việt Nam | AQ21: 147 | AR21: 43 | AS21: 1000 | AU21: =VLOOKUP(CP21,'TT DO DAC'!$B$2:$G$213,5,0) -> Chi nhánh xí nghiệp tài nguyên và môi trường 7 | AX21: =VLOOKUP(CP21,'TT DO DAC'!$B$2:$G$213,6,0) -> 41274 | AY21: A | BB21: Đất chuyên trồng lúa | BC21: =VLOOKUP(BB21,DM_LoaiDat!$B$2:$C$78,2,0) -> LUC | BD21: =BC21 -> LUC | BE21: 678 | BF21: 0 | BG21: Đến ngày 17/08/2067 | BI21: DG-KTT | BJ21: =VLOOKUP(BI21,DM_NguonGocSuDungDat!$A$2:$B$24,2,0) -> Nhà nước giao đất không thu tiền sử dụng đất | CP21: xã Dực Yên, huyện Đầm Hà, tỉnh Quảng Ninh | CQ21: Thôn Tây, xã Dực Yên, huyện Đầm Hà, tỉnh Quảng Ninh | CT21: 0 | CV21: Giấy chứng nhận QSDĐ & QSHNƠ và TSKGLVĐ theo NĐ 88/NĐ-CP | CW21: CH 00493 | CY21: 25/02/2021 | CZ21: Lê Bình Phượng | DA21: 0 | DB21: 1 | DC21: 2021 | GB21: CT 909068
A22: 11 | B22: CT 909068 | C22: =RIGHT(D22,6) -> 005376 | D22: 0691019005376 | F22: GDC | G22: 1 | I22: Hoàng Văn Phương | J22: 1 | L22: 1968 | M22: CMND | N22: 100470947 | S22: Thôn Tây | T22: =VLOOKUP(U22,MaXa_3cap_2cap!$B$2:$C$369,2,0) -> 06910 | U22: xã Dực Yên, huyện Đầm Hà, tỉnh Quảng Ninh | V22: Thôn Tây, xã Dực Yên, huyện Đầm Hà, tỉnh Quảng Ninh | Y22: Việt Nam | Z22: Nguyễn Thị Hảo | AA22: 0 | AC22: 1972 | AD22: CMND | AE22: 100691675 | AJ22: Thôn Tây | AK22: =VLOOKUP(AL22,MaXa_3cap_2cap!$B$2:$C$369,2,0) -> 06910 | AL22: xã Dực Yên, huyện Đầm Hà, tỉnh Quảng Ninh | AM22: Thôn Tây, xã Dực Yên, huyện Đầm Hà, tỉnh Quảng Ninh | AP22: Việt Nam | AQ22: 62 | AR22: 43 | AS22: 1000 | AU22: =VLOOKUP(CP22,'TT DO DAC'!$B$2:$G$213,5,0) -> Chi nhánh xí nghiệp tài nguyên và môi trường 7 | AX22: =VLOOKUP(CP22,'TT DO DAC'!$B$2:$G$213,6,0) -> 41274 | AY22: A | BB22: Đất chuyên trồng lúa | BC22: =VLOOKUP(BB22,DM_LoaiDat!$B$2:$C$78,2,0) -> LUC | BD22: =BC22 -> LUC | BE22: 161.1 | BF22: 0 | BG22: Đến ngày 17/08/2067 | BI22: DG-KTT | BJ22: =VLOOKUP(BI22,DM_NguonGocSuDungDat!$A$2:$B$24,2,0) -> Nhà nước giao đất không thu tiền sử dụng đất | CP22: xã Dực Yên, huyện Đầm Hà, tỉnh Quảng Ninh | CQ22: Thôn Tây, xã Dực Yên, huyện Đầm Hà, tỉnh Quảng Ninh | CT22: 0 | CV22: Giấy chứng nhận QSDĐ & QSHNƠ và TSKGLVĐ theo NĐ 88/NĐ-CP | CW22: CH 00493 | CY22: 25/02/2021 | CZ22: Lê Bình Phượng | DA22: 0 | DB22: 1 | DC22: 2021 | GB22: CT 909068
A23: 12 | B23: CT 909068 | C23: =RIGHT(D23,6) -> 005376 | D23: 0691019005376 | F23: GDC | G23: 1 | I23: Hoàng Văn Phương | J23: 1 | L23: 1968 | M23: CMND | N23: 100470947 | S23: Thôn Tây | T23: =VLOOKUP(U23,MaXa_3cap_2cap!$B$2:$C$369,2,0) -> 06910 | U23: xã Dực Yên, huyện Đầm Hà, tỉnh Quảng Ninh | V23: Thôn Tây, xã Dực Yên, huyện Đầm Hà, tỉnh Quảng Ninh | Y23: Việt Nam | Z23: Nguyễn Thị Hảo | AA23: 0 | AC23: 1972 | AD23: CMND | AE23: 100691675 | AJ23: Thôn Tây | AK23: =VLOOKUP(AL23,MaXa_3cap_2cap!$B$2:$C$369,2,0) -> 06910 | AL23: xã Dực Yên, huyện Đầm Hà, tỉnh Quảng Ninh | AM23: Thôn Tây, xã Dực Yên, huyện Đầm Hà, tỉnh Quảng Ninh | AP23: Việt Nam | AQ23: 51 | AR23: 43 | AS23: 1000 | AU23: =VLOOKUP(CP23,'TT DO DAC'!$B$2:$G$213,5,0) -> Chi nhánh xí nghiệp tài nguyên và môi trường 7 | AX23: =VLOOKUP(CP23,'TT DO DAC'!$B$2:$G$213,6,0) -> 41274 | AY23: A | BB23: Đất chuyên trồng lúa | BC23: =VLOOKUP(BB23,DM_LoaiDat!$B$2:$C$78,2,0) -> LUC | BD23: =BC23 -> LUC | BE23: 284.9 | BF23: 0 | BG23: Đến ngày 17/08/2067 | BI23: DG-KTT | BJ23: =VLOOKUP(BI23,DM_NguonGocSuDungDat!$A$2:$B$24,2,0) -> Nhà nước giao đất không thu tiền sử dụng đất | CP23: xã Dực Yên, huyện Đầm Hà, tỉnh Quảng Ninh | CQ23: Thôn Tây, xã Dực Yên, huyện Đầm Hà, tỉnh Quảng Ninh | CT23: 0 | CV23: Giấy chứng nhận QSDĐ & QSHNƠ và TSKGLVĐ theo NĐ 88/NĐ-CP | CW23: CH 00493 | CY23: 25/02/2021 | CZ23: Lê Bình Phượng | DA23: 0 | DB23: 1 | DC23: 2021 | GB23: CT 909068
A24: 0.64444444 | C24: =RIGHT(D24,6)
A25: 13 | B25: CT 909072 | C25: =RIGHT(D25,6) -> 005380 | D25: 0691019005380 | F25: GDC | G25: 1 | I25: Nguyễn Văn Vĩnh | J25: 1 | L25: 1966 | M25: CCCD | N25: 031066001610 | S25: Thôn Tây | T25: =VLOOKUP(U25,MaXa_3cap_2cap!$B$2:$C$369,2,0) -> 06910 | U25: xã Dực Yên, huyện Đầm Hà, tỉnh Quảng Ninh | V25: Thôn Tây, xã Dực Yên, huyện Đầm Hà, tỉnh Quảng Ninh | Y25: Việt Nam | Z25: Đỗ Thị Nền | AA25: 0 | AC25: 1960 | AD25: CMND | AE25: 101068774 | AJ25: Thôn Tây | AK25: =VLOOKUP(AL25,MaXa_3cap_2cap!$B$2:$C$369,2,0) -> 06910 | AL25: xã Dực Yên, huyện Đầm Hà, tỉnh Quảng Ninh | AM25: Thôn Tây, xã Dực Yên, huyện Đầm Hà, tỉnh Quảng Ninh | AP25: Việt Nam | AQ25: 75 | AR25: 52 | AS25: 1000 | AU25: =VLOOKUP(CP25,'TT DO DAC'!$B$2:$G$213,5,0) -> Chi nhánh xí nghiệp tài nguyên và môi trường 7 | AX25: =VLOOKUP(CP25,'TT DO DAC'!$B$2:$G$213,6,0) -> 41274 | AY25: A | BB25: Đất trồng lúa còn lại | BC25: =VLOOKUP(BB25,DM_LoaiDat!$B$2:$C$78,2,0) -> LUK | BD25: =BC25 -> LUK | BE25: 166.5 | BF25: 0 | BG25: Đến ngày 17/08/2067 | BI25: DG-KTT | BJ25: =VLOOKUP(BI25,DM_NguonGocSuDungDat!$A$2:$B$24,2,0) -> Nhà nước giao đất không thu tiền sử dụng đất | CP25: xã Dực Yên, huyện Đầm Hà, tỉnh Quảng Ninh | CQ25: Thôn Tây, xã Dực Yên, huyện Đầm Hà, tỉnh Quảng Ninh | CT25: 0 | CV25: Giấy chứng nhận QSDĐ & QSHNƠ và TSKGLVĐ theo NĐ 88/NĐ-CP | CW25: CH 00526 | CY25: 19/03/2021 | DA25: 0 | DB25: 1 | DC25: 2021 | GB25: CT909066
A26: 14 | B26: CT 909072 | C26: =RIGHT(D26,6) -> 005380 | D26: 0691019005380 | F26: GDC | G26: 1 | I26: Nguyễn Văn Vĩnh | J26: 1 | L26: 1966 | M26: CCCD | N26: 031066001610 | S26: Thôn Tây | T26: =VLOOKUP(U26,MaXa_3cap_2cap!$B$2:$C$369,2,0) -> 06910 | U26: xã Dực Yên, huyện Đầm Hà, tỉnh Quảng Ninh | V26: Thôn Tây, xã Dực Yên, huyện Đầm Hà, tỉnh Quảng Ninh | Y26: Việt Nam | Z26: Đỗ Thị Nền | AA26: 0 | AC26: 1960 | AD26: CMND | AE26: 101068774 | AJ26: Thôn Tây | AK26: =VLOOKUP(AL26,MaXa_3cap_2cap!$B$2:$C$369,2,0) -> 06910 | AL26: xã Dực Yên, huyện Đầm Hà, tỉnh Quảng Ninh | AM26: Thôn Tây, xã Dực Yên, huyện Đầm Hà, tỉnh Quảng Ninh | AP26: Việt Nam | AQ26: 74 | AR26: 52 | AS26: 1000 | AU26: =VLOOKUP(CP26,'TT DO DAC'!$B$2:$G$213,5,0) -> Chi nhánh xí nghiệp tài nguyên và môi trường 7 | AX26: =VLOOKUP(CP26,'TT DO DAC'!$B$2:$G$213,6,0) -> 41274 | AY26: A | BB26: Đất trồng lúa còn lại | BC26: =VLOOKUP(BB26,DM_LoaiDat!$B$2:$C$78,2,0) -> LUK | BD26: =BC26 -> LUK | BE26: 112.7 | BF26: 0 | BG26: Đến ngày 17/08/2067 | BI26: DG-KTT | BJ26: =VLOOKUP(BI26,DM_NguonGocSuDungDat!$A$2:$B$24,2,0) -> Nhà nước giao đất không thu tiền sử dụng đất | CP26: xã Dực Yên, huyện Đầm Hà, tỉnh Quảng Ninh | CQ26: Thôn Tây, xã Dực Yên, huyện Đầm Hà, tỉnh Quảng Ninh | CT26: 0 | CV26: Giấy chứng nhận QSDĐ & QSHNƠ và TSKGLVĐ theo NĐ 88/NĐ-CP | CW26: CH 00526 | CY26: 19/03/2022 | DA26: 0 | DB26: 1 | DC26: 2021 | GB26: CT909066
A27: 15 | B27: CT 909072 | C27: =RIGHT(D27,6) -> 005380 | D27: 0691019005380 | F27: GDC | G27: 1 | I27: Nguyễn Văn Vĩnh | J27: 1 | L27: 1966 | M27: CCCD | N27: 031066001610 | S27: Thôn Tây | T27: =VLOOKUP(U27,MaXa_3cap_2cap!$B$2:$C$369,2,0) -> 06910 | U27: xã Dực Yên, huyện Đầm Hà, tỉnh Quảng Ninh | V27: Thôn Tây, xã Dực Yên, huyện Đầm Hà, tỉnh Quảng Ninh | Y27: Việt Nam | Z27: Đỗ Thị Nền | AA27: 0 | AC27: 1960 | AD27: CMND | AE27: 101068774 | AJ27: Thôn Tây | AK27: =VLOOKUP(AL27,MaXa_3cap_2cap!$B$2:$C$369,2,0) -> 06910 | AL27: xã Dực Yên, huyện Đầm Hà, tỉnh Quảng Ninh | AM27: Thôn Tây, xã Dực Yên, huyện Đầm Hà, tỉnh Quảng Ninh | AP27: Việt Nam | AQ27: 73 | AR27: 52 | AS27: 1000 | AU27: =VLOOKUP(CP27,'TT DO DAC'!$B$2:$G$213,5,0) -> Chi nhánh xí nghiệp tài nguyên và môi trường 7 | AX27: =VLOOKUP(CP27,'TT DO DAC'!$B$2:$G$213,6,0) -> 41274 | AY27: A | BB27: Đất trồng lúa còn lại | BC27: =VLOOKUP(BB27,DM_LoaiDat!$B$2:$C$78,2,0) -> LUK | BD27: =BC27 -> LUK | BE27: 114.3 | BF27: 0 | BG27: Đến ngày 17/08/2067 | BI27: DG-KTT | BJ27: =VLOOKUP(BI27,DM_NguonGocSuDungDat!$A$2:$B$24,2,0) -> Nhà nước giao đất không thu tiền sử dụng đất | CP27: xã Dực Yên, huyện Đầm Hà, tỉnh Quảng Ninh | CQ27: Thôn Tây, xã Dực Yên, huyện Đầm Hà, tỉnh Quảng Ninh | CT27: 0 | CV27: Giấy chứng nhận QSDĐ & QSHNƠ và TSKGLVĐ theo NĐ 88/NĐ-CP | CW27: CH 00526 | CY27: 19/03/2023 | DA27: 0 | DB27: 1 | DC27: 2021 | GB27: CT909066
A28: 16 | B28: CT 909072 | C28: =RIGHT(D28,6) -> 005380 | D28: 0691019005380 | F28: GDC | G28: 1 | I28: Nguyễn Văn Vĩnh | J28: 1 | L28: 1966 | M28: CCCD | N28: 031066001610 | S28: Thôn Tây | T28: =VLOOKUP(U28,MaXa_3cap_2cap!$B$2:$C$369,2,0) -> 06910 | U28: xã Dực Yên, huyện Đầm Hà, tỉnh Quảng Ninh | V28: Thôn Tây, xã Dực Yên, huyện Đầm Hà, tỉnh Quảng Ninh | Y28: Việt Nam | Z28: Đỗ Thị Nền | AA28: 0 | AC28: 1960 | AD28: CMND | AE28: 101068774 | AJ28: Thôn Tây | AK28: =VLOOKUP(AL28,MaXa_3cap_2cap!$B$2:$C$369,2,0) -> 06910 | AL28: xã Dực Yên, huyện Đầm Hà, tỉnh Quảng Ninh | AM28: Thôn Tây, xã Dực Yên, huyện Đầm Hà, tỉnh Quảng Ninh | AP28: Việt Nam | AQ28: 31 | AR28: 52 | AS28: 1000 | AU28: =VLOOKUP(CP28,'TT DO DAC'!$B$2:$G$213,5,0) -> Chi nhánh xí nghiệp tài nguyên và môi trường 7 | AX28: =VLOOKUP(CP28,'TT DO DAC'!$B$2:$G$213,6,0) -> 41274 | AY28: A | BB28: Đất trồng lúa còn lại | BC28: =VLOOKUP(BB28,DM_LoaiDat!$B$2:$C$78,2,0) -> LUK | BD28: =BC28 -> LUK | BE28: 188.3 | BF28: 0 | BG28: Đến ngày 17/08/2067 | BI28: DG-KTT | BJ28: =VLOOKUP(BI28,DM_NguonGocSuDungDat!$A$2:$B$24,2,0) -> Nhà nước giao đất không thu tiền sử dụng đất | CP28: xã Dực Yên, huyện Đầm Hà, tỉnh Quảng Ninh | CQ28: Thôn Tây, xã Dực Yên, huyện Đầm Hà, tỉnh Quảng Ninh | CT28: 0 | CV28: Giấy chứng nhận QSDĐ & QSHNƠ và TSKGLVĐ theo NĐ 88/NĐ-CP | CW28: CH 00526 | CY28: 19/03/2024 | DA28: 0 | DB28: 1 | DC28: 2021 | GB28: CT909066
A29: 17 | B29: CT 909073 | C29: =RIGHT(D29,6) -> 005380 | D29: 0691019005380 | F29: GDC | G29: 1 | I29: Nguyễn Văn Vĩnh | J29: 1 | L29: 1966 | M29: CCCD | N29: 031066001610 | S29: Thôn Tây | T29: =VLOOKUP(U29,MaXa_3cap_2cap!$B$2:$C$369,2,0) -> 06910 | U29: xã Dực Yên, huyện Đầm Hà, tỉnh Quảng Ninh | V29: Thôn Tây, xã Dực Yên, huyện Đầm Hà, tỉnh Quảng Ninh | Y29: Việt Nam | Z29: Đỗ Thị Nền | AA29: 0 | AC29: 1960 | AD29: CMND | AE29: 101068774 | AJ29: Thôn Tây | AK29: =VLOOKUP(AL29,MaXa_3cap_2cap!$B$2:$C$369,2,0) -> 06910 | AL29: xã Dực Yên, huyện Đầm Hà, tỉnh Quảng Ninh | AM29: Thôn Tây, xã Dực Yên, huyện Đầm Hà, tỉnh Quảng Ninh | AP29: Việt Nam | AQ29: 21 | AR29: 52 | AS29: 1000 | AU29: =VLOOKUP(CP29,'TT DO DAC'!$B$2:$G$213,5,0) -> Chi nhánh xí nghiệp tài nguyên và môi trường 7 | AX29: =VLOOKUP(CP29,'TT DO DAC'!$B$2:$G$213,6,0) -> 41274 | AY29: A | BB29: Đất trồng lúa còn lại | BC29: =VLOOKUP(BB29,DM_LoaiDat!$B$2:$C$78,2,0) -> LUK | BD29: =BC29 -> LUK | BE29: 109.5 | BF29: 0 | BG29: Đến ngày 17/08/2067 | BI29: DG-KTT | BJ29: =VLOOKUP(BI29,DM_NguonGocSuDungDat!$A$2:$B$24,2,0) -> Nhà nước giao đất không thu tiền sử dụng đất | CP29: xã Dực Yên, huyện Đầm Hà, tỉnh Quảng Ninh | CQ29: Thôn Tây, xã Dực Yên, huyện Đầm Hà, tỉnh Quảng Ninh | CT29: 0 | CV29: Giấy chứng nhận QSDĐ & QSHNƠ và TSKGLVĐ theo NĐ 88/NĐ-CP | CW29: CH 00526 | CY29: 19/03/2025 | DA29: 0 | DB29: 1 | DC29: 2021 | GB29: CT909066
A30: 0.66319444 | C30: =RIGHT(D30,6)
A31: 18 | B31: CT 909084 | C31: =RIGHT(D31,6) -> 005392 | D31: 0691019005392 | F31: GDC | G31: 1 | I31: Nguyễn Văn Vinh | J31: 1 | L31: 1971 | M31: CMND | N31: 100881850 | S31: Thôn Tây | T31: =VLOOKUP(U31,MaXa_3cap_2cap!$B$2:$C$369,2,0) -> 06910 | U31: xã Dực Yên, huyện Đầm Hà, tỉnh Quảng Ninh | V31: Thôn Tây, xã Dực Yên, huyện Đầm Hà, tỉnh Quảng Ninh | Y31: Việt Nam | Z31: Hoàng Thị Xuân | AA31: 0 | AC31: 1974 | AD31: CMND | AE31: 100597556 | AJ31: Thôn Tây | AK31: =VLOOKUP(AL31,MaXa_3cap_2cap!$B$2:$C$369,2,0) -> 06910 | AL31: xã Dực Yên, huyện Đầm Hà, tỉnh Quảng Ninh | AM31: Thôn Tây, xã Dực Yên, huyện Đầm Hà, tỉnh Quảng Ninh | AP31: Việt Nam | AQ31: 264 | AR31: 43 | AS31: 1000 | AU31: =VLOOKUP(CP31,'TT DO DAC'!$B$2:$G$213,5,0) -> Chi nhánh xí nghiệp tài nguyên và môi trường 7 | AX31: =VLOOKUP(CP31,'TT DO DAC'!$B$2:$G$213,6,0) -> 41274 | AY31: A | BB31: Đất chuyên trồng lúa | BC31: =VLOOKUP(BB31,DM_LoaiDat!$B$2:$C$78,2,0) -> LUC | BD31: =BC31 -> LUC | BE31: 700.8 | BF31: 0 | BG31: Đến ngày 17/08/2067 | BI31: DG-KTT | BJ31: =VLOOKUP(BI31,DM_NguonGocSuDungDat!$A$2:$B$24,2,0) -> Nhà nước giao đất không thu tiền sử dụng đất | CP31: xã Dực Yên, huyện Đầm Hà, tỉnh Quảng Ninh | CQ31: Thôn Tây, xã Dực Yên, huyện Đầm Hà, tỉnh Quảng Ninh | CT31: 0 | CV31: Giấy chứng nhận QSDĐ & QSHNƠ và TSKGLVĐ theo NĐ 88/NĐ-CP | CW31: CH 00477 | CY31: 44084 | CZ31: Lê Bình Phượng | DA31: 0 | DB31: 1 | DC31: 2020 | GB31: CT909084
A32: 19 | B32: CT 909084 | C32: =RIGHT(D32,6) -> 005392 | D32: 0691019005392 | F32: GDC | G32: 1 | I32: Nguyễn Văn Vinh | J32: 1 | L32: 1971 | M32: CMND | N32: 100881850 | S32: Thôn Tây | T32: =VLOOKUP(U32,MaXa_3cap_2cap!$B$2:$C$369,2,0) -> 06910 | U32: xã Dực Yên, huyện Đầm Hà, tỉnh Quảng Ninh | V32: Thôn Tây, xã Dực Yên, huyện Đầm Hà, tỉnh Quảng Ninh | Y32: Việt Nam | Z32: Hoàng Thị Xuân | AA32: 0 | AC32: 1974 | AD32: CMND | AE32: 100597556 | AJ32: Thôn Tây | AK32: =VLOOKUP(AL32,MaXa_3cap_2cap!$B$2:$C$369,2,0) -> 06910 | AL32: xã Dực Yên, huyện Đầm Hà, tỉnh Quảng Ninh | AM32: Thôn Tây, xã Dực Yên, huyện Đầm Hà, tỉnh Quảng Ninh | AP32: Việt Nam | AQ32: 217 | AR32: 43 | AS32: 1000 | AU32: =VLOOKUP(CP32,'TT DO DAC'!$B$2:$G$213,5,0) -> Chi nhánh xí nghiệp tài nguyên và môi trường 7 | AX32: =VLOOKUP(CP32,'TT DO DAC'!$B$2:$G$213,6,0) -> 41274 | AY32: A | BB32: Đất chuyên trồng lúa | BC32: =VLOOKUP(BB32,DM_LoaiDat!$B$2:$C$78,2,0) -> LUC | BD32: =BC32 -> LUC | BE32: 700.3 | BF32: 0 | BG32: Đến ngày 17/08/2067 | BI32: DG-KTT | BJ32: =VLOOKUP(BI32,DM_NguonGocSuDungDat!$A$2:$B$24,2,0) -> Nhà nước giao đất không thu tiền sử dụng đất | CP32: xã Dực Yên, huyện Đầm Hà, tỉnh Quảng Ninh | CQ32: Thôn Tây, xã Dực Yên, huyện Đầm Hà, tỉnh Quảng Ninh | CT32: 0 | CV32: Giấy chứng nhận QSDĐ & QSHNƠ và TSKGLVĐ theo NĐ 88/NĐ-CP | CW32: CH 00477 | CY32: 44084 | CZ32: Lê Bình Phượng | DA32: 0 | DB32: 1 | DC32: 2020 | GB32: CT909084
A33: 20 | B33: CT 909084 | C33: =RIGHT(D33,6) -> 005392 | D33: 0691019005392 | F33: GDC | G33: 1 | I33: Nguyễn Văn Vinh | J33: 1 | L33: 1971 | M33: CMND | N33: 100881850 | S33: Thôn Tây | T33: =VLOOKUP(U33,MaXa_3cap_2cap!$B$2:$C$369,2,0) -> 06910 | U33: xã Dực Yên, huyện Đầm Hà, tỉnh Quảng Ninh | V33: Thôn Tây, xã Dực Yên, huyện Đầm Hà, tỉnh Quảng Ninh | Y33: Việt Nam | Z33: Hoàng Thị Xuân | AA33: 0 | AC33: 1974 | AD33: CMND | AE33: 100597556 | AJ33: Thôn Tây | AK33: =VLOOKUP(AL33,MaXa_3cap_2cap!$B$2:$C$369,2,0) -> 06910 | AL33: xã Dực Yên, huyện Đầm Hà, tỉnh Quảng Ninh | AM33: Thôn Tây, xã Dực Yên, huyện Đầm Hà, tỉnh Quảng Ninh | AP33: Việt Nam | AQ33: 160 | AR33: 43 | AS33: 1000 | AU33: =VLOOKUP(CP33,'TT DO DAC'!$B$2:$G$213,5,0) -> Chi nhánh xí nghiệp tài nguyên và môi trường 7 | AX33: =VLOOKUP(CP33,'TT DO DAC'!$B$2:$G$213,6,0) -> 41274 | AY33: A | BB33: Đất chuyên trồng lúa | BC33: =VLOOKUP(BB33,DM_LoaiDat!$B$2:$C$78,2,0) -> LUC | BD33: =BC33 -> LUC | BE33: 561 | BF33: 0 | BG33: Đến ngày 17/08/2067 | BI33: DG-KTT | BJ33: =VLOOKUP(BI33,DM_NguonGocSuDungDat!$A$2:$B$24,2,0) -> Nhà nước giao đất không thu tiền sử dụng đất | CP33: xã Dực Yên, huyện Đầm Hà, tỉnh Quảng Ninh | CQ33: Thôn Tây, xã Dực Yên, huyện Đầm Hà, tỉnh Quảng Ninh | CT33: 0 | CV33: Giấy chứng nhận QSDĐ & QSHNƠ và TSKGLVĐ theo NĐ 88/NĐ-CP | CW33: CH 00477 | CY33: 44084 | CZ33: Lê Bình Phượng | DA33: 0 | DB33: 1 | DC33: 2020 | GB33: CT909084
A34: 21 | B34: CT 909084 | C34: =RIGHT(D34,6) -> 005392 | D34: 0691019005392 | F34: GDC | G34: 1 | I34: Nguyễn Văn Vinh | J34: 1 | L34: 1971 | M34: CMND | N34: 100881850 | S34: Thôn Tây | T34: =VLOOKUP(U34,MaXa_3cap_2cap!$B$2:$C$369,2,0) -> 06910 | U34: xã Dực Yên, huyện Đầm Hà, tỉnh Quảng Ninh | V34: Thôn Tây, xã Dực Yên, huyện Đầm Hà, tỉnh Quảng Ninh | Y34: Việt Nam | Z34: Hoàng Thị Xuân | AA34: 0 | AC34: 1974 | AD34: CMND | AE34: 100597556 | AJ34: Thôn Tây | AK34: =VLOOKUP(AL34,MaXa_3cap_2cap!$B$2:$C$369,2,0) -> 06910 | AL34: xã Dực Yên, huyện Đầm Hà, tỉnh Quảng Ninh | AM34: Thôn Tây, xã Dực Yên, huyện Đầm Hà, tỉnh Quảng Ninh | AP34: Việt Nam | AQ34: 130 | AR34: 42 | AS34: 1000 | AU34: =VLOOKUP(CP34,'TT DO DAC'!$B$2:$G$213,5,0) -> Chi nhánh xí nghiệp tài nguyên và môi trường 7 | AX34: =VLOOKUP(CP34,'TT DO DAC'!$B$2:$G$213,6,0) -> 41274 | AY34: A | BB34: Đất chuyên trồng lúa | BC34: =VLOOKUP(BB34,DM_LoaiDat!$B$2:$C$78,2,0) -> LUC | BD34: =BC34 -> LUC | BE34: 588.7 | BF34: 0 | BG34: Đến ngày 17/08/2067 | BI34: DG-KTT | BJ34: =VLOOKUP(BI34,DM_NguonGocSuDungDat!$A$2:$B$24,2,0) -> Nhà nước giao đất không thu tiền sử dụng đất | CP34: xã Dực Yên, huyện Đầm Hà, tỉnh Quảng Ninh | CQ34: Thôn Tây, xã Dực Yên, huyện Đầm Hà, tỉnh Quảng Ninh | CT34: 0 | CV34: Giấy chứng nhận QSDĐ & QSHNƠ và TSKGLVĐ theo NĐ 88/NĐ-CP | CW34: CH 00477 | CY34: 44084 | CZ34: Lê Bình Phượng | DA34: 0 | DB34: 1 | DC34: 2020 | GB34: CT909084
A35: 0.67361111 | C35: =RIGHT(D35,6)
A36: 22 | B36: CT 909101 | C36: =RIGHT(D36,6) -> 005145 | D36: 0691019005145 | F36: GDC | G36: 1 | I36: Phạm Minh Tuấn | J36: 1 | L36: 1969 | M36: CCCD | N36: 030069004178 | S36: Thôn Đông | T36: =VLOOKUP(U36,MaXa_3cap_2cap!$B$2:$C$369,2,0) -> 06910 | U36: xã Dực Yên, huyện Đầm Hà, tỉnh Quảng Ninh | V36: Thôn Đông, xã Dực Yên, huyện Đầm Hà, tỉnh Quảng Ninh | Y36: Việt Nam | Z36: Nguyễn Thị Thắm | AA36: 0 | AC36: 1971 | AD36: CCCD | AE36: 022171000831 | AJ36: Thôn Đông | AK36: =VLOOKUP(AL36,MaXa_3cap_2cap!$B$2:$C$369,2,0) -> 06910 | AL36: xã Dực Yên, huyện Đầm Hà, tỉnh Quảng Ninh | AM36: Thôn Đông, xã Dực Yên, huyện Đầm Hà, tỉnh Quảng Ninh | AP36: Việt Nam | AQ36: 311 | AR36: 65 | AS36: 1000 | AU36: =VLOOKUP(CP36,'TT DO DAC'!$B$2:$G$213,5,0) -> Chi nhánh xí nghiệp tài nguyên và môi trường 7 | AX36: =VLOOKUP(CP36,'TT DO DAC'!$B$2:$G$213,6,0) -> 41274 | AY36: A | BB36: Đất trồng cây hằng năm khác | BC36: =VLOOKUP(BB36,DM_LoaiDat!$B$2:$C$78,2,0) -> HNK | BD36: =BC36 -> HNK | BE36: 293,0 | BF36: 0 | BG36: Đến ngày 17/08/2067 | BI36: DG-KTT | BJ36: =VLOOKUP(BI36,DM_NguonGocSuDungDat!$A$2:$B$24,2,0) -> Nhà nước giao đất không thu tiền sử dụng đất | CP36: xã Dực Yên, huyện Đầm Hà, tỉnh Quảng Ninh | CQ36: Thôn Đông, xã Dực Yên, huyện Đầm Hà, tỉnh Quảng Ninh | CT36: 0 | CV36: Giấy chứng nhận QSDĐ & QSHNƠ và TSKGLVĐ theo NĐ 88/NĐ-CP | CW36: CH 002229 | CY36: 44173 | CZ36: Lê Bình Phượng | DA36: 0 | DB36: 1 | DC36: 2020 | GB36: CT909101
A37: 23 | B37: CT 909101 | C37: =RIGHT(D37,6) -> 005145 | D37: 0691019005145 | F37: GDC | G37: 1 | I37: Phạm Minh Tuấn | J37: 1 | L37: 1969 | M37: CCCD | N37: 030069004178 | S37: Thôn Đông | T37: =VLOOKUP(U37,MaXa_3cap_2cap!$B$2:$C$369,2,0) -> 06910 | U37: xã Dực Yên, huyện Đầm Hà, tỉnh Quảng Ninh | V37: Thôn Đông, xã Dực Yên, huyện Đầm Hà, tỉnh Quảng Ninh | Y37: Việt Nam | Z37: Nguyễn Thị Thắm | AA37: 0 | AC37: 1971 | AD37: CCCD | AE37: 022171000831 | AJ37: Thôn Đông | AK37: =VLOOKUP(AL37,MaXa_3cap_2cap!$B$2:$C$369,2,0) -> 06910 | AL37: xã Dực Yên, huyện Đầm Hà, tỉnh Quảng Ninh | AM37: Thôn Đông, xã Dực Yên, huyện Đầm Hà, tỉnh Quảng Ninh | AP37: Việt Nam | AQ37: 259 | AR37: 76 | AS37: 1000 | AU37: =VLOOKUP(CP37,'TT DO DAC'!$B$2:$G$213,5,0) -> Chi nhánh xí nghiệp tài nguyên và môi trường 7 | AX37: =VLOOKUP(CP37,'TT DO DAC'!$B$2:$G$213,6,0) -> 41274 | AY37: A | BB37: Đất trồng cây hằng năm khác | BC37: =VLOOKUP(BB37,DM_LoaiDat!$B$2:$C$78,2,0) -> HNK | BD37: =BC37 -> HNK | BE37: 607,5 | BF37: 0 | BG37: Đến ngày 17/08/2067 | BI37: DG-KTT | BJ37: =VLOOKUP(BI37,DM_NguonGocSuDungDat!$A$2:$B$24,2,0) -> Nhà nước giao đất không thu tiền sử dụng đất | CP37: xã Dực Yên, huyện Đầm Hà, tỉnh Quảng Ninh | CQ37: Thôn Đông, xã Dực Yên, huyện Đầm Hà, tỉnh Quảng Ninh | CT37: 0 | CV37: Giấy chứng nhận QSDĐ & QSHNƠ và TSKGLVĐ theo NĐ 88/NĐ-CP | CW37: CH 002229 | CY37: 44173 | CZ37: Lê Bình Phượng | DA37: 0 | DB37: 1 | DC37: 2020 | GB37: CT909101
A38: 24 | B38: CT 909101 | C38: =RIGHT(D38,6) -> 005145 | D38: 0691019005145 | F38: GDC | G38: 1 | I38: Phạm Minh Tuấn | J38: 1 | L38: 1969 | M38: CCCD | N38: 030069004178 | S38: Thôn Đông | T38: =VLOOKUP(U38,MaXa_3cap_2cap!$B$2:$C$369,2,0) -> 06910 | U38: xã Dực Yên, huyện Đầm Hà, tỉnh Quảng Ninh | V38: Thôn Đông, xã Dực Yên, huyện Đầm Hà, tỉnh Quảng Ninh | Y38: Việt Nam | Z38: Nguyễn Thị Thắm | AA38: 0 | AC38: 1971 | AD38: CCCD | AE38: 022171000831 | AJ38: Thôn Đông | AK38: =VLOOKUP(AL38,MaXa_3cap_2cap!$B$2:$C$369,2,0) -> 06910 | AL38: xã Dực Yên, huyện Đầm Hà, tỉnh Quảng Ninh | AM38: Thôn Đông, xã Dực Yên, huyện Đầm Hà, tỉnh Quảng Ninh | AP38: Việt Nam | AQ38: 310 | AR38: 76 | AS38: 1000 | AU38: =VLOOKUP(CP38,'TT DO DAC'!$B$2:$G$213,5,0) -> Chi nhánh xí nghiệp tài nguyên và môi trường 7 | AX38: =VLOOKUP(CP38,'TT DO DAC'!$B$2:$G$213,6,0) -> 41274 | AY38: A | BB38: Đất trồng lúa còn lại | BC38: =VLOOKUP(BB38,DM_LoaiDat!$B$2:$C$78,2,0) -> LUK | BD38: =BC38 -> LUK | BE38: 265,5 | BF38: 0 | BG38: Đến ngày 17/08/2067 | BI38: DG-KTT | BJ38: =VLOOKUP(BI38,DM_NguonGocSuDungDat!$A$2:$B$24,2,0) -> Nhà nước giao đất không thu tiền sử dụng đất | CP38: xã Dực Yên, huyện Đầm Hà, tỉnh Quảng Ninh | CQ38: Thôn Đông, xã Dực Yên, huyện Đầm Hà, tỉnh Quảng Ninh | CT38: 0 | CV38: Giấy chứng nhận QSDĐ & QSHNƠ và TSKGLVĐ theo NĐ 88/NĐ-CP | CW38: CH 002229 | CY38: 44173 | CZ38: Lê Bình Phượng | DA38: 0 | DB38: 1 | DC38: 2020 | GB38: CT909101
A39: 0.68541667 | C39: =RIGHT(D39,6)
A40: 25 | B40: CM 204646 | C40: =RIGHT(D40,6) -> 002699 | D40: 0691319002699 | F40: GDC | G40: 1 | I40: Nguyễn Hữu Nhượng | J40: 1 | L40: 1982 | M40: CCCD | N40: 022082002195 | S40: Phố Hoàng Ngân | T40: =VLOOKUP(U40,MaXa_3cap_2cap!$B$2:$C$369,2,0) -> 06895 | U40: thị trấn Đầm Hà, huyện Đầm Hà, tỉnh Quảng Ninh | V40: Phố Hoàng Ngân, thị trấn Đầm Hà, huyện Đầm Hà, tỉnh Quảng Ninh | Y40: Việt Nam | Z40: Trịnh Thị Diệu Thúy | AA40: 0 | AC40: 1988 | AD40: CMND | AE40: 100971117 | AJ40: Phố Hoàng Ngân | AK40: =VLOOKUP(AL40,MaXa_3cap_2cap!$B$2:$C$369,2,0) -> 06895 | AL40: thị trấn Đầm Hà, huyện Đầm Hà, tỉnh Quảng Ninh | AM40: Phố Hoàng Ngân, thị trấn Đầm Hà, huyện Đầm Hà, tỉnh Quảng Ninh | AP40: Việt Nam | AQ40: 348 | AR40: 24 | AS40: 1000 | AU40: =VLOOKUP(CP40,'TT DO DAC'!$B$2:$G$213,5,0) -> Chi nhánh xí nghiệp tài nguyên và môi trường 3 | AX40: =VLOOKUP(CP40,'TT DO DAC'!$B$2:$G$213,6,0) -> 41442 | AY40: A | BB40: Đất chuyên trồng lúa | BC40: =VLOOKUP(BB40,DM_LoaiDat!$B$2:$C$78,2,0) -> LUC | BD40: =BC40 -> LUC | BE40: 1318,4 | BF40: 0 | BG40: Đến ngày 17/08/2069 | CP40: xã Quảng Tân, huyện Đầm Hà, tỉnh Quảng Ninh | CQ40: thôn Tân Thanh, xã Quảng Tân, huyện Đầm Hà, tỉnh Quảng Ninh | CT40: 0 | CV40: Giấy chứng nhận QSDĐ & QSHNƠ và TSKGLVĐ theo NĐ 88/NĐ-CP | CW40: CH00160 | CY40: 31/03/2020 | CZ40: Phạm Văn Kha | DA40: 0 | DB40: 1 | DC40: 2020
...

Sheet Sheet1
A1: Tờ bàn đồ số | B1: Thừa đất số | C1: Diện tích (m2) | D1: Hình thức sử dụng | E1: Mục đích sử dụng | F1: Thời hạn sử dụng | G1: Nguồn gổc sử dụng
A2: 52 | B2: 75 | C2: 166,5 | D2: Sử dụng riêng | E2: Đẩt trồng lúa nước còn lạĩ | F2: Đến ngày 17/08/2067 | G2: Nhà nước giao đất không thu tiền sử dụng đất
A3: 52 | B3: 74 | C3: 112,7 | D3: Sử dụng riêng | E3: Đất trồng lúa nước còn lại | F3: Đen ngày 17/08/2067 | G3: Nhà nước giao đất không thu tiền sử dụng đất
A4: 52 | B4: 73 | C4: 114,3/ | D4: Sừ dụng riêng | E4: Đất trồng lúa nước còn lại | F4: Đen ngày 17/08/2067 | G4: Nhà nước giao đất không thu tiền sử dụng đất
A5: 52 | B5: . 31 | C5: 188,3 | D5: Sử dụng riêng | E5: Đất trồng lúa nước còn lại | F5: Đen ngày 17/08/2067 | G5: Nhà nước giao đất không thu tiền sử dụng đất
A6: 52 | B6: 21 | C6: 109,5 | D6: Sử dụng riêng | E6: Đất ừồng lúa nước còn lại | F6: Đen ngày 17/08/2067 | G6: Nhà nước giao đất không thu tiền sử dụng đất
A8: ờ bàn đồ sổ | B8: Thừa đất số | C8: Diện tích (m2) | D8: Hình thức sử dụng | E8: Mục đích sừ dụng | F8: Thời hạn sừ dụng | G8: Nguồn gốc sử dụng | L8: Tờ bản đồ số | M8: Thửa đất số | N8: Diện tích (m1) | O8: Hình thức sử dụng | P8: Mục đích sử dụng | Q8: Thời hạn sử dụng | R8: Nguồn gốc sừ dụng | U8: Tờ bàn đồ số | V8: Thửa đất số | W8: Diện tích (m2) | X8: Hình thức sử dụng | Y8: Mục đích sử dụng | Z8: Thời hạn sử dụng | AA8: Nguồn gốc sử dụng
A9: 43 | B9: 264 | C9: 700,8 | D9: Sử dụng riêng | E9: Đất chuyên trồng lúa nước | F9: Đến ngày 17/08/2067 | G9: Nhà nước giao đất không thu tiền sừ dụng đất | L9: 65 | M9: 311 | N9: 293,0 | O9: Sử dụng riêng | P9: Đẩt bằng trồng cây hàng năm khác | Q9: Đen ngày 17/08/2067 | R9: Nhà nước giao đất không thu tiền sử dụng đẩt | U9: 24 | V9: 348 | W9: 1318,4 | X9: Sừ dụng riêng | Y9: Đất chuyên trồng lúa nước | Z9: 20/06/2065 | AA9: Nhận chuyển nhượng đất được Nhà nước giao đất không thu tiền sử dụng đất
A10: 43 | B10: 217 | C10: 700,3 | D10: Sử dụng riêng | E10: Đất chuyên trong lúa nước | F10: Đen ngày 17/08/2067 | G10: Nhà nước giao đất không thu tiền sù dụng đất | L10: 76 | M10: 259 | N10: 607,5 | O10: Sử dụng riêng | P10: Đất bàng trồng cây hàng nàm khác | Q10: Đen ngày 17/08/2067 | R10: Nhà nước giao đất không thu tiền sừ dụng đất | U10: 24 | V10: 385 | W10: 1008,9 | X10: Sừ dụng riêng | Y10: Đất chuyên trồng lúa nước | Z10: 20/06/2065 | AA10: Nhận chuyển nhượng đất được Nhà nước giao đất không thu tiền sử dụng đất
A11: 43 | B11: 160 | C11: 561,0 | D11: Sử dụng riêng | E11: Đất chuyên trồng lúa nước | F11: Đen ngày 17/08/2067 | G11: Nhà nước giao đất không thu tiền sừ dụng đất | L11: 76 | M11: 310 | N11: 265,5 | O11: Sử dụng riêng | P11: Đất'trồng lúa nước còn lại | Q11: Đến ngày 17/08/2067 | R11: Nhà nước giao đất không thu tiền sử dụng đất
A12: 42 | B12: 130 | C12: 588,7 | D12: Sử dụng riêng | E12: Đất chuyên trồng lúa nước | F12: Đển ngày 17/08/2067 | G12: Nhà nước giao đất không thu tiền sừ dụng đất
A13: 2. Nhà ở: -/-
L16: Tờ bàn đồ số | M16: Thửa đất số | N16: Diện tích (m2) | O16: Hình thức sử dụng | P16: Mục đích sử dụng | Q16: Thời hạn sử dụng | R16: Nguồn gốc sử dụng
L17: 24 | M17: 348 | N17: 1318,4 | O17: Sừ dụng riêng | P17: Đất chuyên trồng lúa nước | Q17: 20/06/2065 | R17: Nhận chuyển nhượng đất được Nhà nước giao đất không thu tiền sử dụng đất
L18: 24 | M18: 385 | N18: 1008,9 | O18: Sừ dụng riêng | P18: Đất chuyên trồng lúa nước | Q18: 20/06/2065 | R18: Nhận chuyển nhượng đất được Nhà nước giao đất không thu tiền sử dụng đất
L21: ờ bản đồ sổ | M21: Thửa đất số | N21: Diện tích (m2) | O21: Hình thức sử dụng | P21: Mục đích sử dụng | Q21: Thời hạn sử dụng | R21: Nguồn gốc sử dụng
L22: 24 | M22: 288 | N22: 191,7 | O22: Sử dụng riêng | P22: Đất trồng cây hàng nãm khác | Q22: 20/06/2065 | R22: Nhận chuyển nhượng đất được Nhà nước giao đất không thu tiền sử dụng đất
L23: 24 | M23: 389 | N23: 252,8 | O23: Sử dụng riêng | P23: Đất chuyên trồng lúa nước | Q23: 20/06/2065 | R23: Nhận chuyển nhượng đất được Nhà nước giao đất không thu tiền sử dụng đất
L24: 24 | M24: 416 | N24: 477,6 | O24: Sử dụng riêng | P24: Đất chuyên trồng lúa nước | Q24: 20/06/2065 | R24: Nhận chuyển nhượng đất được Nhà nước giao đất không thu tiền sử dụng đất

Sheet HuongDan
D1: Lưu ý: Kiểu dữ liệu lô-gic: nhập 1 có là True, 0 là False Giới tính: 1 là Nam, 0 là Nữ | E1: Hướng dẫn thực hiện điều chỉnh cập nhật dữ liệu | F1: Chú thích | G1: Màu cột
A2: STT Cột | B2: Nhóm dữ liệu | C2: Tên cột | D2: Mô tả | H2: Những trường bắt buộc trong Thông tư 75
A3: 1 | B3: Số TT | C3: Số TT | D3: Số thứ tự dòng, bản ghi được đánh từ 1 đến hết | H3: Những trường bổ sung, hỗ trợ bổ sung thông tin đẩy dữ liệu
A4: 2 | B4: Giấy chứng nhận | C4: Số serial | D4: Số serial bìa ghi trên GCN | H4: Bỏ qua không nhập
A5: 3 | C5: Mã HS Gốc | D5: 6 số cuối của mã vạch
A6: 4 | C6: Mã vạch | D6: Mã vạch ghi trên GCN
A7: 5 | B7: Thông tin chủ sử dụng | C7: Mã Chủ SD | D7: Được sinh sau khi xuất dữ liệu từ phần mềm
A8: 6 | C8: ĐTSD | D8: Đối tượng sửu dụng của chủ được quy định theo thông tư của bộ TNMT | F8: Bổ sung những trường còn trống (Đối với tên chủ là cá nhân thì để GDC, tên chủ là Tổ chức thì để theo sheet "DoiTuongSuDung")
A9: 7 | C9: HGD | D9: Thông tin ghi hộ/ ông bà: 1 ghi là Hộ ông/Hộ bà, 0 ghi là Ông/Bà.
A10: 8 | C10: Người đại diện | D10: Là người đại diện cho nhóm người: 1 là đại diện. 0 là không đại diện
A11: 9 | C11: Họ tên | D11: Họ tên chủ của thửa đất
A12: 10 | C12: Giới tính | D12: 0: là nữ ; 1: là nam | E12: Kiểm tra bất thường theo thông tin cột 9 (ví dụ tìm họ tên có chữ lót là thị, nếu giá trị trường số 9 =1, thì điều chỉnh lại =0 và ngược lại, nếu chữ lót là văn , mà giá trị trường số 9=0 thì điều chỉnh ngược lại )
A13: 11 | C13: Ngày, tháng, năm sinh | D13: Là ngày, tháng, năm sinh của chủ (nếu có) | E13: Kiểm tra bất thường ngày tháng năm sinh
A14: 12 | C14: Năm sinh | D14: Năm sinh của chủ thửa đất | E14: Kiểm tra bất thường năm sinh
A15: 13 | C15: Loại GT | D15: Loại giấy tờ pháp lý của chủ (CMND, CMQS, Hộ khẩu, Hộ chiếu, Giấy phép kinh doanh, …)
A16: 14 | C16: Số giấy tờ | D16: Hộ gia đình cá nhân: Nếu có số CMND thì ghi CMND nếu ko có ghi số hộ khẩu Chủ sử dụng tổ chức: ghi số của giấy phép kinh doanh, quyết định thành lập | E16: Kiểm tra độ dài của trường số 14; len CMND =9, CCCD len =12 các bất thường khác kiểm tra trong hồ sơ quét | F16: CMND vẫn có 12 số
A17: 15 | C17: Ngày cấp | D17: Thông tin về ngày cấp giấy tờ của chủ
A18: 16 | C18: Nơi cấp | D18: Tên đơn vị cấp giấy | E18: Chuẩn về 1 tên, nếu nơi cấp trùng nhau; (ví dụ Công an Bình Định; Công an tỉnh Bình định --> Công an tỉnh Bình Định)
A19: 17 | C19: Số nhà, ngõ phố… | D19: địa chỉ chi tiết số nhà, ngõ…
A20: 18 | C20: Đường Phố | D20: Tên đường của chủ
A21: 19 | C21: Tổ dân phố | D21: Tên tổ dân phố chủ
A22: 20 | C22: Mã xã/phường | D22: Mã xã của chủ (5 ký tự, nếu chủ ở nơi khác (trường hợp đất xâm canh) thì phải chỉ ra chủ thuộc xã nào)
A23: 21 | C23: Xã, huyện, tỉnh | D23: Xã, huyện, tỉnh theo địa chỉ chủ
A24: 22 | C24: Địa chỉ đầy đủ | E24: Nếu trống thì đưa vào đơn vị hành chính xã/phường | F24: Bỏ qua cột này
A25: 23 | C25: Mã số thuế | D25: Mã số thuế cá nhân
A26: 24 | C26: Dân tộc | D26: Dân tộc của chủ
A27: 25 | C27: Quốc tịch | D27: Quốc tịch của chủ, mặc định là quốc tịch Việt Nam
A28: 26 | B28: Thông tin vợ (chồng): thực hiện điều chỉnh tương tự như nhóm thông tin Chủ sử dụng | C28: Họ và tên | D28: Họ tên chủ của thửa đất
A29: 27 | C29: Giới tính | D29: 0: là nữ ; 1: là nam
A30: 28 | C30: Ngày, tháng, năm sinh | D30: Là ngày, tháng, năm sinh của chủ (nếu có)
A31: 29 | C31: Năm sinh | D31: Năm sinh của chủ thửa đất
A32: 30 | C32: Loại GT | D32: Loại giấy tờ pháp lý của chủ (CMND, CMQS, Hộ khẩu, Hộ chiếu, Giấy phép kinh doanh, …)
A33: 31 | C33: Số Giấy tờ | D33: Hộ gia đình cá nhân: Nếu có số CMND thì ghi CMND nếu ko có ghi số hộ khẩu Chủ sử dụng tổ chức: ghi số của giấy phép kinh doanh, quyết định thành lập
A34: 32 | C34: Ngày cấp | D34: Thông tin về ngày cấp giấy tờ của chủ
A35: 33 | C35: Nơi cấp | D35: Tên đơn vị cấp giấy
A36: 34 | C36: Số nhà, ngõ phố,… | D36: địa chỉ chi tiết số nhà, ngõ…
A37: 35 | C37: Đường Phố | D37: Tên đường của chủ
A38: 36 | C38: Tổ dân phố | D38: Tên tổ dân phố chủ
A39: 37 | C39: Mã xã/Phường | D39: Mã xã của chủ (5 ký tự, nếu chủ ở nơi khác (trường hợp đất xâm canh) thì phải chỉ ra chủ thuộc xã nào)
A40: 38 | C40: Xã, huyện, tỉnh | D40: Xã, huyện, tỉnh theo địa chỉ chủ
...

Sheet TT DO DAC
A1: STT | C1: Tên phường cũ | D1: Huyện | E1: Tỉnh | F1: Tên đơn vị đo | G1: Ngày hoàn thành
A2: =ROW()-1 -> 1 | B2: =C2&", "&D2&", "&E2 -> Phường Hà Khánh, Thành phố Hạ Long, Tỉnh Quảng Ninh | C2: Phường Hà Khánh | D2: Thành phố Hạ Long | E2: Tỉnh Quảng Ninh | F2: Xí nghiệp tài nguyên và môi trường 3 | G2: 43090
A3: =ROW()-1 -> 2 | B3: =C3&", "&D3&", "&E3 -> Phường Hà Phong, Thành phố Hạ Long, Tỉnh Quảng Ninh | C3: Phường Hà Phong | D3: Thành phố Hạ Long | E3: Tỉnh Quảng Ninh | F3: Xí nghiệp tài nguyên và môi trường 4 | G3: 43081
A4: =ROW()-1 -> 3 | B4: =C4&", "&D4&", "&E4 -> Phường Hà Khẩu, Thành phố Hạ Long, Tỉnh Quảng Ninh | C4: Phường Hà Khẩu | D4: Thành phố Hạ Long | E4: Tỉnh Quảng Ninh | F4: Xí nghiệp trắc địa bàn đồ 203 | G4: 43089
A5: =ROW()-1 -> 4 | B5: =C5&", "&D5&", "&E5 -> Phường Cao Xanh, Thành phố Hạ Long, Tỉnh Quảng Ninh | C5: Phường Cao Xanh | D5: Thành phố Hạ Long | E5: Tỉnh Quảng Ninh | F5: Trung tâm kĩ thuật tài nguyên và môi trương | G5: 43094
A6: =ROW()-1 -> 5 | B6: =C6&", "&D6&", "&E6 -> Phường Giếng Đáy, Thành phố Hạ Long, Tỉnh Quảng Ninh | C6: Phường Giếng Đáy | D6: Thành phố Hạ Long | E6: Tỉnh Quảng Ninh | F6: Chi nhánh công ty TNHH 1 Thành viên tài nguyên và môi trường miền nam | G6: 43091
A7: =ROW()-1 -> 6 | B7: =C7&", "&D7&", "&E7 -> Phường Hà Tu, Thành phố Hạ Long, Tỉnh Quảng Ninh | C7: Phường Hà Tu | D7: Thành phố Hạ Long | E7: Tỉnh Quảng Ninh | F7: Xí nghiệp tài nguyên và môi trường 5 | G7: 43094
A8: =ROW()-1 -> 7 | B8: =C8&", "&D8&", "&E8 -> Phường Hà Trung, Thành phố Hạ Long, Tỉnh Quảng Ninh | C8: Phường Hà Trung | D8: Thành phố Hạ Long | E8: Tỉnh Quảng Ninh | F8: Xí nghiệp tài nguyên và môi trường 3 | G8: 43095
A9: =ROW()-1 -> 8 | B9: =C9&", "&D9&", "&E9 -> Phường Hà Lầm, Thành phố Hạ Long, Tỉnh Quảng Ninh | C9: Phường Hà Lầm | D9: Thành phố Hạ Long | E9: Tỉnh Quảng Ninh | F9: Xí nghiệp tài nguyên và môi trường 3 | G9: 43090
A10: =ROW()-1 -> 9 | B10: =C10&", "&D10&", "&E10 -> Phường Bãi Cháy, Thành phố Hạ Long, Tỉnh Quảng Ninh | C10: Phường Bãi Cháy | D10: Thành phố Hạ Long | E10: Tỉnh Quảng Ninh | F10: Công ty cổ phần đo đạc và khoáng sản | G10: 43096
A11: =ROW()-1 -> 10 | B11: =C11&", "&D11&", "&E11 -> Phường Cao Thắng, Thành phố Hạ Long, Tỉnh Quảng Ninh | C11: Phường Cao Thắng | D11: Thành phố Hạ Long | E11: Tỉnh Quảng Ninh | F11: Đoàn khảo sát đo đạc bản đồ Quảng Ninh | G11: 43098
A12: =ROW()-1 -> 11 | B12: =C12&", "&D12&", "&E12 -> Phường Hùng Thắng, Thành phố Hạ Long, Tỉnh Quảng Ninh | C12: Phường Hùng Thắng | D12: Thành phố Hạ Long | E12: Tỉnh Quảng Ninh | F12: Công ty cổ phần công nghệ tài nguyên môi trường và vật liệu | G12: 43084
A13: =ROW()-1 -> 12 | B13: =C13&", "&D13&", "&E13 -> Phường Trần Hưng Đạo, Thành phố Hạ Long, Tỉnh Quảng Ninh | C13: Phường Trần Hưng Đạo | D13: Thành phố Hạ Long | E13: Tỉnh Quảng Ninh | F13: Công ty cổ phần tài nguyên nam dương | G13: 43094
... A21: =ROW()-1 -> 20 | B21: =C21&", "&D21&", "&E21 -> Yết kiêu, Thành phố Hạ Long, Tỉnh Quảng Ninh | C21: Yết kiêu | D21: Thành phố Hạ Long | E21: Tỉnh Quảng Ninh | F21: Trung tâm kĩ thuật tài nguyên và môi trương | G21: 43090
A22: =ROW()-1 -> 21 | B22: =C22&", "&D22&", "&E22 -> Phường Hoành Bồ, Thành phố Hạ Long, Tỉnh Quảng Ninh | C22: Phường Hoành Bồ | D22: Thành phố Hạ Long | E22: Tỉnh Quảng Ninh
A23: =ROW()-1 -> 22 | B23: =C23&", "&D23&", "&E23 -> Xã Kỳ Thượng, Thành phố Hạ Long, Tỉnh Quảng Ninh | C23: Xã Kỳ Thượng | D23: Thành phố Hạ Long | E23: Tỉnh Quảng Ninh | F23: Xí nghiệp tài nghiệp và môi trường 3 | G23: 03/1/2012
A24: =ROW()-1 -> 23 | B24: =C24&", "&D24&", "&E24 -> Xã Đồng Sơn, Thành phố Hạ Long, Tỉnh Quảng Ninh | C24: Xã Đồng Sơn | D24: Thành phố Hạ Long | E24: Tỉnh Quảng Ninh | F24: Xí nghiệp tài nguyên và môi trường 2, chi nhánh Tổng công ty Tài nguyên và Môi trường Việt Nam | G24: 4/4/2012
